Workbook

Sheet Data 
A1: DATA BALI WASTE CYCLE
A2: ='Setoran 1'!A2:R2 -> TANGGAL : 8 Agustus2026
A4: No | B4: Jenis | C4: HARGA BELI | D4: HARGA JUAL | E4: KETERANGAN
A7: PLASTIK
A8: 1 | B8: Rongsok Campur | C8: 400 | D8: 500 | E8: Campuran plastik kemasan berbentuk dan kaleng (bukan kresek/plastik lembaran)
A9: 2 | B9: PET Kotor | C9: 400 | D9: 500 | E9: Botol dan gelas minum yang masih berlabel tutup (tanpa air/isi)
A10: 3 | B10: PET KW 2 | C10: 300 | D10: 400 | E10: Botol minyak, botol saos sejenis kotor bekas penggunaan
A11: 4 | B11: PET Bersih Bening | C11: 2800 | D11: 3000 | E11: Botol air mineral bening tanpa label & tutup (Ades, Club, Vit Sejenis)
A12: 5 | B12: PET Bersih Biru Muda | C12: 2400 | D12: 2500 | E12: Botol air mineral Biru Muda tanpa label (Aqua, Le Minerale)
A13: 6 | B13: PET Bersih Warna | C13: 700 | D13: 800 | E13: Botol warna tanpa label & tutup (Mizone, Sprite), Tidak termasuk PET putih (Milku)
A14: 7 | B14: PET Bersih Campur | C14: 1600 | D14: 1700 | E14: Botol campur bening dan biru muda tanpa label dan tutup
A15: 8 | B15: Putihan (HDPE & jenis lainnya) | C15: 1800 | D15: 2000 | E15: Botol kosmetik (botol shampo, sabun cair, bedak, botol oli, dll) TANPA ISI
A16: 9 | B16: Jerigen Bening bersih/Jerigen minyak | C16: 2400 | D16: 2500 | E16: Jerigen warna bening seperti jerigen minyak, alkohol, sabun, pewangi, kecap,dll TANPA ISI
A17: 10 | B17: Jerigen warna/bening tapi mangkak | C17: 1900 | D17: 2000 | E17: Jerigen oli, dll yang berwarna TANPA ISI
A18: 11 | B18: Tutup PET (HDPE) | C18: 1800 | D18: 2000 | E18: Tutup botol Aqua, Vit, Pocari, Sprite, dll
A19: 12 | B19: Tutup Galon (LDPE) | C19: 1700 | D19: 1800 | E19: Tutup galon air mineral/isi ulang
A20: 13 | B20: Tutup campur | E20: Tutup HD, LD, PP Campur
A21: 14 | B21: PP Emberan Campur | C21: 900 | D21: 1000 | E21: Jika tercampur hitam ikut harga emberan hitam
A22: 15 | B22: PP Emberan warna | C22: 900 | D22: 1000 | E22: Semua warna kecuali hitam, perabotan RT, piring plastik, meja plastik, kursi plastik, baskom, sikat gigi, sisir (lebih keras dan tipis)
A23: 16 | B23: PP Emberan Hitam | C23: 900 | D23: 1000 | E23: Semua emberan warna hitam (pot bunga, hanger hitam, timba hitam, body hitam, dll)
A24: 17 | B24: PC Galon UTUH (/biji) | C24: 1300 | D24: 1500 | E24: Galon air minuman semua merk kondisi utuh kecuali galon cleo
A25: 18 | B25: PC Galon PECAH (/Kg) | C25: 800 | D25: 1000 | E25: Galon air minuman semua merk kondisi pecah
A26: 19 | B26: Aqua Gelas Kotor | C26: 1100 | D26: 1200 | E26: PP Gelas masih berlabel dan belum di lepas ringnya (Aqua, club) TANPA AIR
A27: 20 | B27: Aqua Gelas Bersih | C27: 1900 | D27: 2000 | E27: PP Gelas BERSIH TANPA Label dan tutup
A28: 21 | B28: Mountea/Sablon | C28: 900 | D28: 1000 | E28: Gelas putih dan bening sablon masih berlabel dan tutup (Mountea, Ale-Ale, Teh Gelas, Teh Rio, Chatime, dll) TANPA AIR
A29: 22 | B29: Plastik Bening PE & PP | C29: 400 | D29: 500 | E29: Plastik kantong bening tanpa label
A30: 23 | B30: HD Kresek | C30: 50 | D30: 100 | E30: Kantong plastik kresek semua warna, polos (non sablon)
A31: 24 | B31: Kresek Campur | C31: 50 | D31: 100 | E31: Plastik yang masih tercampur TANPA MULTILAYER
A32: 25 | B32: LLDPE Pouch/Single Layer | C32: 40 | D32: 50 | E32: Kemasan minyak goreng, sabun cuci cair, sabun cuci piring, kemasan kispray, shampoo refill, dll
... A36: 29 | B36: PVC | C36: 50 | D36: 100 | E36: Pipa, paralon semua warna, pintu plastik, talang air, dll)
A37: KERTAS
A38: 1 | B38: Buku Tulis/Buku Pelajaran | C38: 1100 | D38: 1200 | E38: Semua buku tulis dan pelajaran putih/cetak
A39: 2 | B39: HVS | C39: 1100 | D39: 1200 | E39: Kertas HVS dengan atau tanpa tulisan atau buku cetakan kertas putih
A40: 3 | B40: Kertas Buram/LKS/warna | C40: 450 | D40: 500 | E40: Isi dalam LKS, kertas nota, kertas coklat
A41: 4 | B41: Majalah | C41: 400 | D41: 500 | E41: Kertas art paper mengkilap (majalah, brosur, poster)
A42: 5 | B42: Koran | C42: 1800 | D42: 2000 | E42: Rapi dan bersih
A43: 6 | B43: Duplek | C43: 75 | D43: 100 | E43: Semua kertas tebal berwarna (map, cover buku/majalah, bungkus rokok, kotak makanan, snack, kotak obat, kotak odol, bungkus sabun, kotak susu, dll)
A44: 7 | B44: Kardus | C44: 700 | D44: 800 | E44: Kardus kering berongga
A45: 8 | B45: Kertas Campur | C45: 75 | D45: 100 | E45: Campur buku, HVS, Majalah, tabloid, koran
A46: LOGAM
...

Sheet Setoran 1
A1: REKAP JUAL BELI SAMPAH NASABAH BALI ARUM (BALI WASTE CYCLE)
A2: TANGGAL : 8 Agustus2026
A4: NO | B4: JENIS | C4: BERAT SETORAN | R4: TOTAL
C5: NOMOR INDUK NASABAH
C6: 010 Bernadeth | D6: 042 Bu Intan | E6: 058 Sawitri | F6: 016 K. Nining | G6: 045 Inggrid | H6: 001 Nining | I6: 005 Inka | J6: 059 Edvin | K6: 036 Listina | L6: 041 Yanti
A7: PLASTIK
A8: 1 | B8: Rongsok Campur | C8: 1 | D8: =0.2+0.6 -> 0.8 | G8: 0.44 | I8: 0.81 | J8: 0.45 | L8: 0.58 | R8: =SUM(C8:Q8) -> 4.08
A9: 2 | B9: PET Kotor | R9: =SUM(C9:Q9) -> 0
A10: 3 | B10: PET KW 2 | R10: =SUM(C10:Q10) -> 0
A11: 4 | B11: PET Bersih Bening | R11: =SUM(C11:Q11) -> 0
A12: 5 | B12: PET Bersih Biru Muda | K12: =1.57+1.8+0.69+4.06+3.1+1.83+0.59 -> 13.64 | R12: =SUM(C12:Q12) -> 13.64
A13: 6 | B13: PET Bersih Warna | R13: =SUM(C13:Q13) -> 0
A14: 7 | B14: PET Bersih Campur | F14: 0.5 | G14: 1.23 | I14: 0.7 | K14: =1.81+0.33 -> 2.14 | L14: 2.4 | R14: =SUM(C14:Q14) -> 6.97
A15: PLASTIK RIGID / BERBENTUK
A16: 1 | B16: Putihan (HDPE & jenis lainnya) | D16: 1.6 | F16: =0.2+0.9 -> 1.1 | G16: 2.25 | I16: =1+0.5 -> 1.5 | J16: 0.07 | K16: =1.48+0.66 -> 2.14 | L16: 0.22 | R16: =SUM(C16:Q16) -> 8.88
A17: 2 | B17: Jerigen Bening bersih/ Jirigen minyak | L17: 0.24 | R17: =SUM(C17:Q17) -> 0.24
A18: 3 | B18: Jerigen warna / bening tapi mangkak | R18: =SUM(C18:Q18) -> 0
A19: 4 | B19: Tutup PET (HDPE) | D19: 0.3 | F19: 0.05 | G19: 0.19 | I19: 0.14 | R19: =SUM(C19:Q19) -> 0.68
A20: 5 | B20: Tutup Galon (LDPE) | F20: 0.09 | I20: 0.1 | K20: =1.36 -> 1.36 | L20: 0.27 | R20: =SUM(C20:Q20) -> 1.82
A21: 6 | B21: Tutup campur | R21: =SUM(C21:Q21) -> 0
A22: 7 | B22: PP Emberan Campur | H22: =3.5+0.34 -> 3.84 | R22: =SUM(C22:Q22) -> 3.84
A23: 8 | B23: PP Emberan warna | F23: 0.17 | I23: 0.7 | R23: =SUM(C23:Q23) -> 0.87
A24: 9 | B24: PP Emberan Hitam | R24: =SUM(C24:Q24) -> 0
A25: 10 | B25: PC Galon UTUH / BIJI | R25: =SUM(C25:Q25) -> 0
A26: 11 | B26: PC Galon PECAH / KG | R26: =SUM(C26:Q26) -> 0
A27: GELASAN
A28: 1 | B28: Aqua Gelas Kotor | R28: =SUM(C28:Q28) -> 0
A29: 2 | B29: Aqua Gelas Bersih | R29: =SUM(C29:Q29) -> 0
A30: 3 | B30: Mountea/Sablon | R30: =SUM(C30:Q30) -> 0
A31: PLASTIK FLEKSIBEL / LEMBARAN
A32: 1 | B32: Plastik Bening PE & PP | H32: =0.84+0.23 -> 1.07 | K32: 3.5 | R32: =SUM(C32:Q32) -> 4.57
A33: 2 | B33: HD Kresek | D33: =0.7+0.5 -> 1.2 | G33: 4.4 | H33: 0.62 | R33: =SUM(C33:Q33) -> 6.22
A34: 3 | B34: Kresek Campur | C34: 4.2 | F34: 0.53 | H34: 0.88 | I34: =3+1.93+2.29 -> 7.22 | K34: =2.73+0.2 -> 2.93 | L34: =0.22+0.35 -> 0.57 | R34: =SUM(C34:Q34) -> 16.33
A35: 4 | B35: LLDPE Pouch | R35: =SUM(C35:Q35) -> 0
A36: 5 | B36: PP Sablon lembaran | R36: =SUM(C36:Q36) -> 0
A37: 6 | B37: Multi Layer | F37: 0.25 | H37: 0.77 | I37: 0.58 | K37: 0.75 | R37: =SUM(C37:Q37) -> 2.35
A38: KERASAN
A39: 1 | B39: Kerasan / PS/ ABS | C39: 7.6 | G39: =0.8+0.3 -> 1.1 | H39: =0.48+0.89 -> 1.37 | K39: =0.9+0.36+1+0.6+1.46 -> 4.32 | L39: 0.22 | R39: =SUM(C39:Q39) -> 14.61
A40: 2 | B40: PVC | R40: =SUM(C40:Q40) -> 0
A41: KERTAS
...

Sheet Setoran 2
A1: ='Setoran 1'!A1:R1 -> REKAP JUAL BELI SAMPAH NASABAH BALI ARUM (BALI WASTE CYCLE)
A2: ='Data '!A2:D2 -> TANGGAL : 8 Agustus2026
A4: NO | B4: JENIS | C4: BERAT SETORAN | R4: TOTAL
C5: NOMOR INDUK NASABAH
A7: PLASTIK
A8: 1 | B8: Rongsok Campur | R8: =SUM(C8:Q8) -> 0
A9: 2 | B9: PET Kotor | R9: =SUM(C9:Q9) -> 0
A10: 3 | B10: PET KW 2 | R10: =SUM(C10:Q10) -> 0
A11: 4 | B11: PET Bersih Bening | R11: =SUM(C11:Q11) -> 0
A12: 5 | B12: PET Bersih Biru Muda | R12: =SUM(C12:Q12) -> 0
A13: 6 | B13: PET Bersih Warna | R13: =SUM(C13:Q13) -> 0
A14: 7 | B14: PET Bersih Campur | R14: =SUM(C14:Q14) -> 0
A15: PLASTIK RIGID / BERBENTUK
A16: 1 | B16: Putihan (HDPE & jenis lainnya) | R16: =SUM(C16:Q16) -> 0
A17: 2 | B17: Jerigen Bening bersih/ Jirigen minyak | R17: =SUM(C17:Q17) -> 0
A18: 3 | B18: Jerigen warna / bening tapi mangkak | R18: =SUM(C18:Q18) -> 0
A19: 4 | B19: Tutup PET (HDPE) | R19: =SUM(C19:Q19) -> 0
A20: 5 | B20: Tutup Galon (LDPE) | R20: =SUM(C20:Q20) -> 0
A21: 6 | B21: Tutup campur | R21: =SUM(C21:Q21) -> 0
A22: 7 | B22: PP Emberan Campur | R22: =SUM(C22:Q22) -> 0
A23: 8 | B23: PP Emberan warna | R23: =SUM(C23:Q23) -> 0
A24: 9 | B24: PP Emberan Hitam | R24: =SUM(C24:Q24) -> 0
A25: 10 | B25: PC Galon UTUH / BIJI | R25: =SUM(C25:Q25) -> 0
A26: 11 | B26: PC Galon PECAH / KG | R26: =SUM(C26:Q26) -> 0
A27: GELASAN
A28: 1 | B28: Aqua Gelas Kotor | R28: =SUM(C28:Q28) -> 0
A29: 2 | B29: Aqua Gelas Bersih | R29: =SUM(C29:Q29) -> 0
A30: 3 | B30: Mountea/Sablon | R30: =SUM(C30:Q30) -> 0
A31: PLASTIK FLEKSIBEL / LEMBARAN
A32: 1 | B32: Plastik Bening PE & PP | R32: =SUM(C32:Q32) -> 0
A33: 2 | B33: HD Kresek | R33: =SUM(C33:Q33) -> 0
A34: 3 | B34: Kresek Campur | R34: =SUM(C34:Q34) -> 0
A35: 4 | B35: LLDPE Pouch | R35: =SUM(C35:Q35) -> 0
A36: 5 | B36: PP Sablon lembaran | R36: =SUM(C36:Q36) -> 0
A37: 6 | B37: Multi Layer | R37: =SUM(C37:Q37) -> 0
A38: KERASAN
A39: 1 | B39: Kerasan / PS/ ABS | R39: =SUM(C39:Q39) -> 0
A40: 2 | B40: PVC | R40: =SUM(C40:Q40) -> 0
A41: KERTAS
A42: 1 | B42: Buku Tulis/Buku Pelajaran | R42: =SUM(C42:Q42) -> 0
...

Sheet Setoran 3
A1: ='Setoran 1'!A1:R1 -> REKAP JUAL BELI SAMPAH NASABAH BALI ARUM (BALI WASTE CYCLE)
A2: ='Data '!A2:D2 -> TANGGAL : 8 Agustus2026
A4: NO | B4: JENIS | C4: BERAT SETORAN | R4: TOTAL
C5: NOMOR INDUK NASABAH
A7: PLASTIK
A8: 1 | B8: Rongsok Campur | R8: =SUM(C8:Q8) -> 0
A9: 2 | B9: PET Kotor | R9: =SUM(C9:Q9) -> 0
A10: 3 | B10: PET KW 2 | R10: =SUM(C10:Q10) -> 0
A11: 4 | B11: PET Bersih Bening | R11: =SUM(C11:Q11) -> 0
A12: 5 | B12: PET Bersih Biru Muda | R12: =SUM(C12:Q12) -> 0
A13: 6 | B13: PET Bersih Warna | R13: =SUM(C13:Q13) -> 0
A14: 7 | B14: PET Bersih Campur | R14: =SUM(C14:Q14) -> 0
A15: PLASTIK RIGID / BERBENTUK
A16: 1 | B16: Putihan (HDPE & jenis lainnya) | R16: =SUM(C16:Q16) -> 0
A17: 2 | B17: Jerigen Bening bersih/ Jirigen minyak | R17: =SUM(C17:Q17) -> 0
A18: 3 | B18: Jerigen warna / bening tapi mangkak | R18: =SUM(C18:Q18) -> 0
A19: 4 | B19: Tutup PET (HDPE) | R19: =SUM(C19:Q19) -> 0
A20: 5 | B20: Tutup Galon (LDPE) | R20: =SUM(C20:Q20) -> 0
A21: 6 | B21: Tutup campur | R21: =SUM(C21:Q21) -> 0
A22: 7 | B22: PP Emberan Campur | R22: =SUM(C22:Q22) -> 0
A23: 8 | B23: PP Emberan warna | R23: =SUM(C23:Q23) -> 0
A24: 9 | B24: PP Emberan Hitam | R24: =SUM(C24:Q24) -> 0
A25: 10 | B25: PC Galon UTUH / BIJI | R25: =SUM(C25:Q25) -> 0
A26: 11 | B26: PC Galon PECAH / KG | R26: =SUM(C26:Q26) -> 0
A27: GELASAN
A28: 1 | B28: Aqua Gelas Kotor | R28: =SUM(C28:Q28) -> 0
A29: 2 | B29: Aqua Gelas Bersih | R29: =SUM(C29:Q29) -> 0
A30: 3 | B30: Mountea/Sablon | R30: =SUM(C30:Q30) -> 0
A31: PLASTIK FLEKSIBEL / LEMBARAN
A32: 1 | B32: Plastik Bening PE & PP | R32: =SUM(C32:Q32) -> 0
A33: 2 | B33: HD Kresek | R33: =SUM(C33:Q33) -> 0
A34: 3 | B34: Kresek Campur | R34: =SUM(C34:Q34) -> 0
A35: 4 | B35: LLDPE Pouch | R35: =SUM(C35:Q35) -> 0
A36: 5 | B36: PP Sablon lembaran | R36: =SUM(C36:Q36) -> 0
A37: 6 | B37: Multi Layer | R37: =SUM(C37:Q37) -> 0
A38: KERASAN
A39: 1 | B39: Kerasan / PS/ ABS | R39: =SUM(C39:Q39) -> 0
A40: 2 | B40: PVC | R40: =SUM(C40:Q40) -> 0
A41: KERTAS
A42: 1 | B42: Buku Tulis/Buku Pelajaran | R42: =SUM(C42:Q42) -> 0
...

Sheet Rekap 1
A1: ='Setoran 1'!A1:R1 -> REKAP JUAL BELI SAMPAH NASABAH BALI ARUM (BALI WASTE CYCLE)
A2: ='Data '!A2 -> TANGGAL : 8 Agustus2026
A4: NO | B4: JENIS | C4: HARGA BELI | D4: HARGA JUAL | E4: NOMOR INDUK NASABAH | AX4: TOTAL | AY4: TOTAL BELI | AZ4: TOTAL JUAL | BA4: MARGIN
E5: ='Setoran 1'!C6 -> 010 Bernadeth | H5: ='Setoran 1'!D6 -> 042 Bu Intan | K5: ='Setoran 1'!E6 -> 058 Sawitri | N5: ='Setoran 1'!F6 -> 016 K. Nining | Q5: ='Setoran 1'!G6 -> 045 Inggrid | T5: ='Setoran 1'!H6 -> 001 Nining | W5: ='Setoran 1'!I6 -> 005 Inka | Z5: ='Setoran 1'!J6 -> 059 Edvin | AC5: ='Setoran 1'!K6 -> 036 Listina | AF5: ='Setoran 1'!L6 -> 041 Yanti | AI5: ='Setoran 1'!M6 -> 0 | AL5: ='Setoran 1'!N6 -> 0 | AO5: ='Setoran 1'!O6 -> 0 | AR5: ='Setoran 1'!P6 -> 0 | AU5: ='Setoran 1'!Q6 -> 0
E6: Berat Setoran | F6: Total Harga Beli | G6: Total Harga Jual | H6: Berat Setoran | I6: Total Harga Beli | J6: Total Harga Jual | K6: Berat Setoran | L6: Total Harga Beli | M6: Total Harga Jual | N6: Berat Setoran | O6: Total Harga Beli | P6: Total Harga Jual | Q6: Berat Setoran | R6: Total Harga Beli | S6: Total Harga Jual | T6: Berat Setoran | U6: Total Harga Beli | V6: Total Harga Jual | W6: Berat Setoran | X6: Total Harga Beli | Y6: Total Harga Jual | Z6: Berat Setoran | AA6: Total Harga Beli | AB6: Total Harga Jual | AC6: Berat Setoran | AD6: Total Harga Beli | AE6: Total Harga Jual | AF6: Berat Setoran | AG6: Total Harga Beli | AH6: Total Harga Jual | AI6: Berat Setoran | AJ6: Total Harga Beli | AK6: Total Harga Jual | AL6: Berat Setoran | AM6: Total Harga Beli | AN6: Total Harga Jual | AO6: Berat Setoran | AP6: Total Harga Beli | AQ6: Total Harga Jual | AR6: Berat Setoran | AS6: Total Harga Beli | AT6: Total Harga Jual | AU6: Berat Setoran | AV6: Total Harga Beli | AW6: Total Harga Jual
A7: PLASTIK
A8: 1 | B8: Rongsok Campur | C8: ='Data '!C8 -> 400 | D8: ='Data '!D8 -> 500 | E8: ='Setoran 1'!C8 -> 1 | F8: =E8*$C8 -> 400 | G8: =E8*$D8 -> 500 | H8: ='Setoran 1'!D8 -> 0.8 | I8: =H8*$C8 -> 320 | J8: =H8*$D8 -> 400 | K8: ='Setoran 1'!E8 -> 0 | L8: =K8*$C8 -> 0 | M8: =K8*$D8 -> 0 | N8: ='Setoran 1'!F8 -> 0 | O8: =N8*$C8 -> 0 | P8: =N8*$D8 -> 0 | Q8: ='Setoran 1'!G8 -> 0.44 | R8: =Q8*$C8 -> 176 | S8: =Q8*$D8 -> 220 | T8: ='Setoran 1'!H8 -> 0 | U8: =T8*$C8 -> 0 | V8: =T8*$D8 -> 0 | W8: ='Setoran 1'!I8 -> 0.81 | X8: =W8*$C8 -> 324 | Y8: =W8*$D8 -> 405 | Z8: ='Setoran 1'!J8 -> 0.45 | AA8: =Z8*$C8 -> 180 | AB8: =Z8*$D8 -> 225 | AC8: ='Setoran 1'!K8 -> 0 | AD8: =AC8*$C8 -> 0 | AE8: =AC8*$D8 -> 0 | AF8: ='Setoran 1'!L8 -> 0.58 | AG8: =AF8*$C8 -> 232 | AH8: =AF8*$D8 -> 290 | AI8: ='Setoran 1'!M8 -> 0 | AJ8: =AI8*$C8 -> 0 | AK8: =AI8*$D8 -> 0 | AL8: ='Setoran 1'!N8 -> 0 | AM8: =AL8*$C8 -> 0 | AN8: =AL8*$D8 -> 0 | AO8: ='Setoran 1'!O8 -> 0 | AP8: =AO8*$C8 -> 0 | AQ8: =AO8*$D8 -> 0 | AR8: ='Setoran 1'!P8 -> 0 | AS8: =AR8*$C8 -> 0 | AT8: =AR8*$D8 -> 0 | AU8: ='Setoran 1'!Q8 -> 0 | AV8: =AU8*$C8 -> 0 | AW8: =AU8*$D8 -> 0 | AX8: =SUM(E8,H8,K8,N8,Q8,T8,W8,Z8,AC8,AF8,AI8,AL8,AO8,AR8,AU8) -> 4.08 | AY8: =SUM(F8,I8,L8,O8,R8,U8,X8,AA8,AD8,,AG8,AJ8,AM8,AP8,AS8,AV8) -> 1632 | AZ8: =SUM(G8,J8,M8,P8,S8,V8,Y8,AB8,AE8,AH8,AK8,AN8,AQ8,AT8,AW8) -> 2040 | BA8: =AZ8-AY8 -> 408
A9: 2 | B9: PET Kotor | C9: ='Data '!C9 -> 400 | D9: ='Data '!D9 -> 500 | E9: ='Setoran 1'!C9 -> 0 | F9: =E9*C9 -> 0 | G9: =E9*D9 -> 0 | H9: ='Setoran 1'!D9 -> 0 | I9: =H9*$C9 -> 0 | J9: =H9*$D9 -> 0 | K9: ='Setoran 1'!E9 -> 0 | L9: =K9*$C9 -> 0 | M9: =K9*$D9 -> 0 | N9: ='Setoran 1'!F9 -> 0 | O9: =N9*$C9 -> 0 | P9: =N9*$D9 -> 0 | Q9: ='Setoran 1'!G9 -> 0 | R9: =Q9*$C9 -> 0 | S9: =Q9*$D9 -> 0 | T9: ='Setoran 1'!H9 -> 0 | U9: =T9*$C9 -> 0 | V9: =T9*$D9 -> 0 | W9: ='Setoran 1'!I9 -> 0 | X9: =W9*$C9 -> 0 | Y9: =W9*$D9 -> 0 | Z9: ='Setoran 1'!J9 -> 0 | AA9: =Z9*$C9 -> 0 | AB9: =Z9*$D9 -> 0 | AC9: ='Setoran 1'!K9 -> 0 | AD9: =AC9*$C9 -> 0 | AE9: =AC9*$D9 -> 0 | AF9: ='Setoran 1'!L9 -> 0 | AG9: =AF9*$C9 -> 0 | AH9: =AF9*$D9 -> 0 | AI9: ='Setoran 1'!M9 -> 0 | AJ9: =AI9*$C9 -> 0 | AK9: =AI9*$D9 -> 0 | AL9: ='Setoran 1'!N9 -> 0 | AM9: =AL9*$C9 -> 0 | AN9: =AL9*$D9 -> 0 | AO9: ='Setoran 1'!O9 -> 0 | AP9: =AO9*$C9 -> 0 | AQ9: =AO9*$D9 -> 0 | AR9: ='Setoran 1'!P9 -> 0 | AS9: =AR9*$C9 -> 0 | AT9: =AR9*$D9 -> 0 | AU9: ='Setoran 1'!Q9 -> 0 | AV9: =AU9*$C9 -> 0 | AW9: =AU9*$D9 -> 0 | AX9: =SUM(E9,H9,K9,N9,Q9,T9,W9,Z9,AC9,AF9,AI9,AL9,AO9,AR9,AU9) -> 0 | AY9: =SUM(F9,I9,L9,O9,R9,U9,X9,AA9,AD9,,AG9,AJ9,AM9,AP9,AS9,AV9) -> 0 | AZ9: =SUM(G9,J9,M9,P9,S9,V9,Y9,AB9,AE9,AH9,AK9,AN9,AQ9,AT9,AW9) -> 0 | BA9: =AZ9-AY9 -> 0
A10: 3 | B10: PET KW 2 | C10: ='Data '!C10 -> 300 | D10: ='Data '!D10 -> 400 | E10: ='Setoran 1'!C10 -> 0 | F10: =E10*C10 -> 0 | G10: =E10*D10 -> 0 | H10: ='Setoran 1'!D10 -> 0 | I10: =H10*$C10 -> 0 | J10: =H10*$D10 -> 0 | K10: ='Setoran 1'!E10 -> 0 | L10: =K10*$C10 -> 0 | M10: =K10*$D10 -> 0 | N10: ='Setoran 1'!F10 -> 0 | O10: =N10*$C10 -> 0 | P10: =N10*$D10 -> 0 | Q10: ='Setoran 1'!G10 -> 0 | R10: =Q10*$C10 -> 0 | S10: =Q10*$D10 -> 0 | T10: ='Setoran 1'!H10 -> 0 | U10: =T10*$C10 -> 0 | V10: =T10*$D10 -> 0 | W10: ='Setoran 1'!I10 -> 0 | X10: =W10*$C10 -> 0 | Y10: =W10*$D10 -> 0 | Z10: ='Setoran 1'!J10 -> 0 | AA10: =Z10*$C10 -> 0 | AB10: =Z10*$D10 -> 0 | AC10: ='Setoran 1'!K10 -> 0 | AD10: =AC10*$C10 -> 0 | AE10: =AC10*$D10 -> 0 | AF10: ='Setoran 1'!L10 -> 0 | AG10: =AF10*$C10 -> 0 | AH10: =AF10*$D10 -> 0 | AI10: ='Setoran 1'!M10 -> 0 | AJ10: =AI10*$C10 -> 0 | AK10: =AI10*$D10 -> 0 | AL10: ='Setoran 1'!N10 -> 0 | AM10: =AL10*$C10 -> 0 | AN10: =AL10*$D10 -> 0 | AO10: ='Setoran 1'!O10 -> 0 | AP10: =AO10*$C10 -> 0 | AQ10: =AO10*$D10 -> 0 | AR10: ='Setoran 1'!P10 -> 0 | AS10: =AR10*$C10 -> 0 | AT10: =AR10*$D10 -> 0 | AU10: ='Setoran 1'!Q10 -> 0 | AV10: =AU10*$C10 -> 0 | AW10: =AU10*$D10 -> 0 | AX10: =SUM(E10,H10,K10,N10,Q10,T10,W10,Z10,AC10,AF10,AI10,AL10,AO10,AR10,AU10) -> 0 | AY10: =SUM(F10,I10,L10,O10,R10,U10,X10,AA10,AD10,,AG10,AJ10,AM10,AP10,AS10,AV10) -> 0 | AZ10: =SUM(G10,J10,M10,P10,S10,V10,Y10,AB10,AE10,AH10,AK10,AN10,AQ10,AT10,AW10) -> 0 | BA10: =AZ10-AY10 -> 0
A11: 4 | B11: PET Bersih Bening | C11: ='Data '!C11 -> 2800 | D11: ='Data '!D11 -> 3000 | E11: ='Setoran 1'!C11 -> 0 | F11: =E11*C11 -> 0 | G11: =E11*D11 -> 0 | H11: ='Setoran 1'!D11 -> 0 | I11: =H11*$C11 -> 0 | J11: =H11*$D11 -> 0 | K11: ='Setoran 1'!E11 -> 0 | L11: =K11*$C11 -> 0 | M11: =K11*$D11 -> 0 | N11: ='Setoran 1'!F11 -> 0 | O11: =N11*$C11 -> 0 | P11: =N11*$D11 -> 0 | Q11: ='Setoran 1'!G11 -> 0 | R11: =Q11*$C11 -> 0 | S11: =Q11*$D11 -> 0 | T11: ='Setoran 1'!H11 -> 0 | U11: =T11*$C11 -> 0 | V11: =T11*$D11 -> 0 | W11: ='Setoran 1'!I11 -> 0 | X11: =W11*$C11 -> 0 | Y11: =W11*$D11 -> 0 | Z11: ='Setoran 1'!J11 -> 0 | AA11: =Z11*$C11 -> 0 | AB11: =Z11*$D11 -> 0 | AC11: ='Setoran 1'!K11 -> 0 | AD11: =AC11*$C11 -> 0 | AE11: =AC11*$D11 -> 0 | AF11: ='Setoran 1'!L11 -> 0 | AG11: =AF11*$C11 -> 0 | AH11: =AF11*$D11 -> 0 | AI11: ='Setoran 1'!M11 -> 0 | AJ11: =AI11*$C11 -> 0 | AK11: =AI11*$D11 -> 0 | AL11: ='Setoran 1'!N11 -> 0 | AM11: =AL11*$C11 -> 0 | AN11: =AL11*$D11 -> 0 | AO11: ='Setoran 1'!O11 -> 0 | AP11: =AO11*$C11 -> 0 | AQ11: =AO11*$D11 -> 0 | AR11: ='Setoran 1'!P11 -> 0 | AS11: =AR11*$C11 -> 0 | AT11: =AR11*$D11 -> 0 | AU11: ='Setoran 1'!Q11 -> 0 | AV11: =AU11*$C11 -> 0 | AW11: =AU11*$D11 -> 0 | AX11: =SUM(E11,H11,K11,N11,Q11,T11,W11,Z11,AC11,AF11,AI11,AL11,AO11,AR11,AU11) -> 0 | AY11: =SUM(F11,I11,L11,O11,R11,U11,X11,AA11,AD11,,AG11,AJ11,AM11,AP11,AS11,AV11) -> 0 | AZ11: =SUM(G11,J11,M11,P11,S11,V11,Y11,AB11,AE11,AH11,AK11,AN11,AQ11,AT11,AW11) -> 0 | BA11: =AZ11-AY11 -> 0
A12: 5 | B12: PET Bersih Biru Muda | C12: ='Data '!C12 -> 2400 | D12: ='Data '!D12 -> 2500 | E12: ='Setoran 1'!C12 -> 0 | F12: =E12*C12 -> 0 | G12: =E12*D12 -> 0 | H12: ='Setoran 1'!D12 -> 0 | I12: =H12*$C12 -> 0 | J12: =H12*$D12 -> 0 | K12: ='Setoran 1'!E12 -> 0 | L12: =K12*$C12 -> 0 | M12: =K12*$D12 -> 0 | N12: ='Setoran 1'!F12 -> 0 | O12: =N12*$C12 -> 0 | P12: =N12*$D12 -> 0 | Q12: ='Setoran 1'!G12 -> 0 | R12: =Q12*$C12 -> 0 | S12: =Q12*$D12 -> 0 | T12: ='Setoran 1'!H12 -> 0 | U12: =T12*$C12 -> 0 | V12: =T12*$D12 -> 0 | W12: ='Setoran 1'!I12 -> 0 | X12: =W12*$C12 -> 0 | Y12: =W12*$D12 -> 0 | Z12: ='Setoran 1'!J12 -> 0 | AA12: =Z12*$C12 -> 0 | AB12: =Z12*$D12 -> 0 | AC12: ='Setoran 1'!K12 -> 13.64 | AD12: =AC12*$C12 -> 32736 | AE12: =AC12*$D12 -> 34100 | AF12: ='Setoran 1'!L12 -> 0 | AG12: =AF12*$C12 -> 0 | AH12: =AF12*$D12 -> 0 | AI12: ='Setoran 1'!M12 -> 0 | AJ12: =AI12*$C12 -> 0 | AK12: =AI12*$D12 -> 0 | AL12: ='Setoran 1'!N12 -> 0 | AM12: =AL12*$C12 -> 0 | AN12: =AL12*$D12 -> 0 | AO12: ='Setoran 1'!O12 -> 0 | AP12: =AO12*$C12 -> 0 | AQ12: =AO12*$D12 -> 0 | AR12: ='Setoran 1'!P12 -> 0 | AS12: =AR12*$C12 -> 0 | AT12: =AR12*$D12 -> 0 | AU12: ='Setoran 1'!Q12 -> 0 | AV12: =AU12*$C12 -> 0 | AW12: =AU12*$D12 -> 0 | AX12: =SUM(E12,H12,K12,N12,Q12,T12,W12,Z12,AC12,AF12,AI12,AL12,AO12,AR12,AU12) -> 13.64 | AY12: =SUM(F12,I12,L12,O12,R12,U12,X12,AA12,AD12,,AG12,AJ12,AM12,AP12,AS12,AV12) -> 32736 | AZ12: =SUM(G12,J12,M12,P12,S12,V12,Y12,AB12,AE12,AH12,AK12,AN12,AQ12,AT12,AW12) -> 34100 | BA12: =AZ12-AY12 -> 1364
A13: 6 | B13: PET Bersih Warna | C13: ='Data '!C13 -> 700 | D13: ='Data '!D13 -> 800 | E13: ='Setoran 1'!C13 -> 0 | F13: =E13*C13 -> 0 | G13: =E13*D13 -> 0 | H13: ='Setoran 1'!D13 -> 0 | I13: =H13*$C13 -> 0 | J13: =H13*$D13 -> 0 | K13: ='Setoran 1'!E13 -> 0 | L13: =K13*$C13 -> 0 | M13: =K13*$D13 -> 0 | N13: ='Setoran 1'!F13 -> 0 | O13: =N13*$C13 -> 0 | P13: =N13*$D13 -> 0 | Q13: ='Setoran 1'!G13 -> 0 | R13: =Q13*$C13 -> 0 | S13: =Q13*$D13 -> 0 | T13: ='Setoran 1'!H13 -> 0 | U13: =T13*$C13 -> 0 | V13: =T13*$D13 -> 0 | W13: ='Setoran 1'!I13 -> 0 | X13: =W13*$C13 -> 0 | Y13: =W13*$D13 -> 0 | Z13: ='Setoran 1'!J13 -> 0 | AA13: =Z13*$C13 -> 0 | AB13: =Z13*$D13 -> 0 | AC13: ='Setoran 1'!K13 -> 0 | AD13: =AC13*$C13 -> 0 | AE13: =AC13*$D13 -> 0 | AF13: ='Setoran 1'!L13 -> 0 | AG13: =AF13*$C13 -> 0 | AH13: =AF13*$D13 -> 0 | AI13: ='Setoran 1'!M13 -> 0 | AJ13: =AI13*$C13 -> 0 | AK13: =AI13*$D13 -> 0 | AL13: ='Setoran 1'!N13 -> 0 | AM13: =AL13*$C13 -> 0 | AN13: =AL13*$D13 -> 0 | AO13: ='Setoran 1'!O13 -> 0 | AP13: =AO13*$C13 -> 0 | AQ13: =AO13*$D13 -> 0 | AR13: ='Setoran 1'!P13 -> 0 | AS13: =AR13*$C13 -> 0 | AT13: =AR13*$D13 -> 0 | AU13: ='Setoran 1'!Q13 -> 0 | AV13: =AU13*$C13 -> 0 | AW13: =AU13*$D13 -> 0 | AX13: =SUM(E13,H13,K13,N13,Q13,T13,W13,Z13,AC13,AF13,AI13,AL13,AO13,AR13,AU13) -> 0 | AY13: =SUM(F13,I13,L13,O13,R13,U13,X13,AA13,AD13,,AG13,AJ13,AM13,AP13,AS13,AV13) -> 0 | AZ13: =SUM(G13,J13,M13,P13,S13,V13,Y13,AB13,AE13,AH13,AK13,AN13,AQ13,AT13,AW13) -> 0 | BA13: =AZ13-AY13 -> 0
A14: 7 | B14: PET Bersih Campur | C14: ='Data '!C14 -> 1600 | D14: ='Data '!D14 -> 1700 | E14: ='Setoran 1'!C14 -> 0 | F14: =E14*C14 -> 0 | G14: =E14*D14 -> 0 | H14: ='Setoran 1'!D14 -> 0 | I14: =H14*$C14 -> 0 | J14: =H14*$D14 -> 0 | K14: ='Setoran 1'!E14 -> 0 | L14: =K14*$C14 -> 0 | M14: =K14*$D14 -> 0 | N14: ='Setoran 1'!F14 -> 0.5 | O14: =N14*$C14 -> 800 | P14: =N14*$D14 -> 850 | Q14: ='Setoran 1'!G14 -> 1.23 | R14: =Q14*$C14 -> 1968 | S14: =Q14*$D14 -> 2091 | T14: ='Setoran 1'!H14 -> 0 | U14: =T14*$C14 -> 0 | V14: =T14*$D14 -> 0 | W14: ='Setoran 1'!I14 -> 0.7 | X14: =W14*$C14 -> 1120 | Y14: =W14*$D14 -> 1190 | Z14: ='Setoran 1'!J14 -> 0 | AA14: =Z14*$C14 -> 0 | AB14: =Z14*$D14 -> 0 | AC14: ='Setoran 1'!K14 -> 2.14 | AD14: =AC14*$C14 -> 3424 | AE14: =AC14*$D14 -> 3638 | AF14: ='Setoran 1'!L14 -> 2.4 | AG14: =AF14*$C14 -> 3840 | AH14: =AF14*$D14 -> 4080 | AI14: ='Setoran 1'!M14 -> 0 | AJ14: =AI14*$C14 -> 0 | AK14: =AI14*$D14 -> 0 | AL14: ='Setoran 1'!N14 -> 0 | AM14: =AL14*$C14 -> 0 | AN14: =AL14*$D14 -> 0 | AO14: ='Setoran 1'!O14 -> 0 | AP14: =AO14*$C14 -> 0 | AQ14: =AO14*$D14 -> 0 | AR14: ='Setoran 1'!P14 -> 0 | AS14: =AR14*$C14 -> 0 | AT14: =AR14*$D14 -> 0 | AU14: ='Setoran 1'!Q14 -> 0 | AV14: =AU14*$C14 -> 0 | AW14: =AU14*$D14 -> 0 | AX14: =SUM(E14,H14,K14,N14,Q14,T14,W14,Z14,AC14,AF14,AI14,AL14,AO14,AR14,AU14) -> 6.97 | AY14: =SUM(F14,I14,L14,O14,R14,U14,X14,AA14,AD14,,AG14,AJ14,AM14,AP14,AS14,AV14) -> 11152 | AZ14: =SUM(G14,J14,M14,P14,S14,V14,Y14,AB14,AE14,AH14,AK14,AN14,AQ14,AT14,AW14) -> 11849 | BA14: =AZ14-AY14 -> 697
A15: PLASTIK RIGID / BERBENTUK
A16: 1 | B16: Putihan (HDPE & jenis lainnya) | C16: ='Data '!C15 -> 1800 | D16: ='Data '!D15 -> 2000 | E16: ='Setoran 1'!C16 -> 0 | F16: =E16*C16 -> 0 | G16: =E16*D16 -> 0 | H16: ='Setoran 1'!D16 -> 1.6 | I16: =H16*$C16 -> 2880 | J16: =H16*$D16 -> 3200 | K16: ='Setoran 1'!E16 -> 0 | L16: =K16*$C16 -> 0 | M16: =K16*$D16 -> 0 | N16: ='Setoran 1'!F16 -> 1.1 | O16: =N16*$C16 -> 1980 | P16: =N16*$D16 -> 2200 | Q16: ='Setoran 1'!G16 -> 2.25 | R16: =Q16*$C16 -> 4050 | S16: =Q16*$D16 -> 4500 | T16: ='Setoran 1'!H16 -> 0 | U16: =T16*$C16 -> 0 | V16: =T16*$D16 -> 0 | W16: ='Setoran 1'!I16 -> 1.5 | X16: =W16*$C16 -> 2700 | Y16: =W16*$D16 -> 3000 | Z16: ='Setoran 1'!J16 -> 0.07 | AA16: =Z16*$C16 -> 126 | AB16: =Z16*$D16 -> 140 | AC16: ='Setoran 1'!K16 -> 2.14 | AD16: =AC16*$C16 -> 3852 | AE16: =AC16*$D16 -> 4280 | AF16: ='Setoran 1'!L16 -> 0.22 | AG16: =AF16*$C16 -> 396 | AH16: =AF16*$D16 -> 440 | AI16: ='Setoran 1'!M16 -> 0 | AJ16: =AI16*$C16 -> 0 | AK16: =AI16*$D16 -> 0 | AL16: ='Setoran 1'!N16 -> 0 | AM16: =AL16*$C16 -> 0 | AN16: =AL16*$D16 -> 0 | AO16: ='Setoran 1'!O16 -> 0 | AP16: =AO16*$C16 -> 0 | AQ16: =AO16*$D16 -> 0 | AR16: ='Setoran 1'!P16 -> 0 | AS16: =AR16*$C16 -> 0 | AT16: =AR16*$D16 -> 0 | AU16: ='Setoran 1'!Q16 -> 0 | AV16: =AU16*$C16 -> 0 | AW16: =AU16*$D16 -> 0 | AX16: =SUM(E16,H16,K16,N16,Q16,T16,W16,Z16,AC16,AF16,AI16,AL16,AO16,AR16,AU16) -> 8.88 | AY16: =SUM(F16,I16,L16,O16,R16,U16,X16,AA16,AD16,,AG16,AJ16,AM16,AP16,AS16,AV16) -> 15984 | AZ16: =SUM(G16,J16,M16,P16,S16,V16,Y16,AB16,AE16,AH16,AK16,AN16,AQ16,AT16,AW16) -> 17760 | BA16: =AZ16-AY16 -> 1776
A17: 2 | B17: Jerigen Bening bersih/ Jirigen minyak | C17: ='Data '!C16 -> 2400 | D17: ='Data '!D16 -> 2500 | E17: ='Setoran 1'!C17 -> 0 | F17: =E17*C17 -> 0 | G17: =E17*D17 -> 0 | H17: ='Setoran 1'!D17 -> 0 | I17: =H17*$C17 -> 0 | J17: =H17*$D17 -> 0 | K17: ='Setoran 1'!E17 -> 0 | L17: =K17*$C17 -> 0 | M17: =K17*$D17 -> 0 | N17: ='Setoran 1'!F17 -> 0 | O17: =N17*$C17 -> 0 | P17: =N17*$D17 -> 0 | Q17: ='Setoran 1'!G17 -> 0 | R17: =Q17*$C17 -> 0 | S17: =Q17*$D17 -> 0 | T17: ='Setoran 1'!H17 -> 0 | U17: =T17*$C17 -> 0 | V17: =T17*$D17 -> 0 | W17: ='Setoran 1'!I17 -> 0 | X17: =W17*$C17 -> 0 | Y17: =W17*$D17 -> 0 | Z17: ='Setoran 1'!J17 -> 0 | AA17: =Z17*$C17 -> 0 | AB17: =Z17*$D17 -> 0 | AC17: ='Setoran 1'!K17 -> 0 | AD17: =AC17*$C17 -> 0 | AE17: =AC17*$D17 -> 0 | AF17: ='Setoran 1'!L17 -> 0.24 | AG17: =AF17*$C17 -> 576 | AH17: =AF17*$D17 -> 600 | AI17: ='Setoran 1'!M17 -> 0 | AJ17: =AI17*$C17 -> 0 | AK17: =AI17*$D17 -> 0 | AL17: ='Setoran 1'!N17 -> 0 | AM17: =AL17*$C17 -> 0 | AN17: =AL17*$D17 -> 0 | AO17: ='Setoran 1'!O17 -> 0 | AP17: =AO17*$C17 -> 0 | AQ17: =AO17*$D17 -> 0 | AR17: ='Setoran 1'!P17 -> 0 | AS17: =AR17*$C17 -> 0 | AT17: =AR17*$D17 -> 0 | AU17: ='Setoran 1'!Q17 -> 0 | AV17: =AU17*$C17 -> 0 | AW17: =AU17*$D17 -> 0 | AX17: =SUM(E17,H17,K17,N17,Q17,T17,W17,Z17,AC17,AF17,AI17,AL17,AO17,AR17,AU17) -> 0.24 | AY17: =SUM(F17,I17,L17,O17,R17,U17,X17,AA17,AD17,,AG17,AJ17,AM17,AP17,AS17,AV17) -> 576 | AZ17: =SUM(G17,J17,M17,P17,S17,V17,Y17,AB17,AE17,AH17,AK17,AN17,AQ17,AT17,AW17) -> 600 | BA17: =AZ17-AY17 -> 24
A18: 3 | B18: Jerigen warna / bening tapi mangkak | C18: ='Data '!C17 -> 1900 | D18: ='Data '!D17 -> 2000 | E18: ='Setoran 1'!C18 -> 0 | F18: =E18*C18 -> 0 | G18: =E18*D18 -> 0 | H18: ='Setoran 1'!D18 -> 0 | I18: =H18*$C18 -> 0 | J18: =H18*$D18 -> 0 | K18: ='Setoran 1'!E18 -> 0 | L18: =K18*$C18 -> 0 | M18: =K18*$D18 -> 0 | N18: ='Setoran 1'!F18 -> 0 | O18: =N18*$C18 -> 0 | P18: =N18*$D18 -> 0 | Q18: ='Setoran 1'!G18 -> 0 | R18: =Q18*$C18 -> 0 | S18: =Q18*$D18 -> 0 | T18: ='Setoran 1'!H18 -> 0 | U18: =T18*$C18 -> 0 | V18: =T18*$D18 -> 0 | W18: ='Setoran 1'!I18 -> 0 | X18: =W18*$C18 -> 0 | Y18: =W18*$D18 -> 0 | Z18: ='Setoran 1'!J18 -> 0 | AA18: =Z18*$C18 -> 0 | AB18: =Z18*$D18 -> 0 | AC18: ='Setoran 1'!K18 -> 0 | AD18: =AC18*$C18 -> 0 | AE18: =AC18*$D18 -> 0 | AF18: ='Setoran 1'!L18 -> 0 | AG18: =AF18*$C18 -> 0 | AH18: =AF18*$D18 -> 0 | AI18: ='Setoran 1'!M18 -> 0 | AJ18: =AI18*$C18 -> 0 | AK18: =AI18*$D18 -> 0 | AL18: ='Setoran 1'!N18 -> 0 | AM18: =AL18*$C18 -> 0 | AN18: =AL18*$D18 -> 0 | AO18: ='Setoran 1'!O18 -> 0 | AP18: =AO18*$C18 -> 0 | AQ18: =AO18*$D18 -> 0 | AR18: ='Setoran 1'!P18 -> 0 | AS18: =AR18*$C18 -> 0 | AT18: =AR18*$D18 -> 0 | AU18: ='Setoran 1'!Q18 -> 0 | AV18: =AU18*$C18 -> 0 | AW18: =AU18*$D18 -> 0 | AX18: =SUM(E18,H18,K18,N18,Q18,T18,W18,Z18,AC18,AF18,AI18,AL18,AO18,AR18,AU18) -> 0 | AY18: =SUM(F18,I18,L18,O18,R18,U18,X18,AA18,AD18,,AG18,AJ18,AM18,AP18,AS18,AV18) -> 0 | AZ18: =SUM(G18,J18,M18,P18,S18,V18,Y18,AB18,AE18,AH18,AK18,AN18,AQ18,AT18,AW18) -> 0 | BA18: =AZ18-AY18 -> 0
A19: 4 | B19: Tutup PET (HDPE) | C19: ='Data '!C18 -> 1800 | D19: ='Data '!D18 -> 2000 | E19: ='Setoran 1'!C19 -> 0 | F19: =E19*C19 -> 0 | G19: =E19*D19 -> 0 | H19: ='Setoran 1'!D19 -> 0.3 | I19: =H19*$C19 -> 540 | J19: =H19*$D19 -> 600 | K19: ='Setoran 1'!E19 -> 0 | L19: =K19*$C19 -> 0 | M19: =K19*$D19 -> 0 | N19: ='Setoran 1'!F19 -> 0.05 | O19: =N19*$C19 -> 90 | P19: =N19*$D19 -> 100 | Q19: ='Setoran 1'!G19 -> 0.19 | R19: =Q19*$C19 -> 342 | S19: =Q19*$D19 -> 380 | T19: ='Setoran 1'!H19 -> 0 | U19: =T19*$C19 -> 0 | V19: =T19*$D19 -> 0 | W19: ='Setoran 1'!I19 -> 0.14 | X19: =W19*$C19 -> 252 | Y19: =W19*$D19 -> 280 | Z19: ='Setoran 1'!J19 -> 0 | AA19: =Z19*$C19 -> 0 | AB19: =Z19*$D19 -> 0 | AC19: ='Setoran 1'!K19 -> 0 | AD19: =AC19*$C19 -> 0 | AE19: =AC19*$D19 -> 0 | AF19: ='Setoran 1'!L19 -> 0 | AG19: =AF19*$C19 -> 0 | AH19: =AF19*$D19 -> 0 | AI19: ='Setoran 1'!M19 -> 0 | AJ19: =AI19*$C19 -> 0 | AK19: =AI19*$D19 -> 0 | AL19: ='Setoran 1'!N19 -> 0 | AM19: =AL19*$C19 -> 0 | AN19: =AL19*$D19 -> 0 | AO19: ='Setoran 1'!O19 -> 0 | AP19: =AO19*$C19 -> 0 | AQ19: =AO19*$D19 -> 0 | AR19: ='Setoran 1'!P19 -> 0 | AS19: =AR19*$C19 -> 0 | AT19: =AR19*$D19 -> 0 | AU19: ='Setoran 1'!Q19 -> 0 | AV19: =AU19*$C19 -> 0 | AW19: =AU19*$D19 -> 0 | AX19: =SUM(E19,H19,K19,N19,Q19,T19,W19,Z19,AC19,AF19,AI19,AL19,AO19,AR19,AU19) -> 0.68 | AY19: =SUM(F19,I19,L19,O19,R19,U19,X19,AA19,AD19,,AG19,AJ19,AM19,AP19,AS19,AV19) -> 1224 | AZ19: =SUM(G19,J19,M19,P19,S19,V19,Y19,AB19,AE19,AH19,AK19,AN19,AQ19,AT19,AW19) -> 1360 | BA19: =AZ19-AY19 -> 136
A20: 5 | B20: Tutup Galon (LDPE) | C20: ='Data '!C19 -> 1700 | D20: ='Data '!D19 -> 1800 | E20: ='Setoran 1'!C20 -> 0 | F20: =E20*C20 -> 0 | G20: =E20*D20 -> 0 | H20: ='Setoran 1'!D20 -> 0 | I20: =H20*$C20 -> 0 | J20: =H20*$D20 -> 0 | K20: ='Setoran 1'!E20 -> 0 | L20: =K20*$C20 -> 0 | M20: =K20*$D20 -> 0 | N20: ='Setoran 1'!F20 -> 0.09 | O20: =N20*$C20 -> 153 | P20: =N20*$D20 -> 162 | Q20: ='Setoran 1'!G20 -> 0 | R20: =Q20*$C20 -> 0 | S20: =Q20*$D20 -> 0 | T20: ='Setoran 1'!H20 -> 0 | U20: =T20*$C20 -> 0 | V20: =T20*$D20 -> 0 | W20: ='Setoran 1'!I20 -> 0.1 | X20: =W20*$C20 -> 170 | Y20: =W20*$D20 -> 180 | Z20: ='Setoran 1'!J20 -> 0 | AA20: =Z20*$C20 -> 0 | AB20: =Z20*$D20 -> 0 | AC20: ='Setoran 1'!K20 -> 1.36 | AD20: =AC20*$C20 -> 2312 | AE20: =AC20*$D20 -> 2448 | AF20: ='Setoran 1'!L20 -> 0.27 | AG20: =AF20*$C20 -> 459 | AH20: =AF20*$D20 -> 486 | AI20: ='Setoran 1'!M20 -> 0 | AJ20: =AI20*$C20 -> 0 | AK20: =AI20*$D20 -> 0 | AL20: ='Setoran 1'!N20 -> 0 | AM20: =AL20*$C20 -> 0 | AN20: =AL20*$D20 -> 0 | AO20: ='Setoran 1'!O20 -> 0 | AP20: =AO20*$C20 -> 0 | AQ20: =AO20*$D20 -> 0 | AR20: ='Setoran 1'!P20 -> 0 | AS20: =AR20*$C20 -> 0 | AT20: =AR20*$D20 -> 0 | AU20: ='Setoran 1'!Q20 -> 0 | AV20: =AU20*$C20 -> 0 | AW20: =AU20*$D20 -> 0 | AX20: =SUM(E20,H20,K20,N20,Q20,T20,W20,Z20,AC20,AF20,AI20,AL20,AO20,AR20,AU20) -> 1.82 | AY20: =SUM(F20,I20,L20,O20,R20,U20,X20,AA20,AD20,,AG20,AJ20,AM20,AP20,AS20,AV20) -> 3094 | AZ20: =SUM(G20,J20,M20,P20,S20,V20,Y20,AB20,AE20,AH20,AK20,AN20,AQ20,AT20,AW20) -> 3276 | BA20: =AZ20-AY20 -> 182
A21: 6 | B21: Tutup campur | C21: ='Data '!C20 -> 0 | D21: ='Data '!D20 -> 0 | E21: ='Setoran 1'!C21 -> 0 | F21: =E21*C21 -> 0 | G21: =E21*D21 -> 0 | H21: ='Setoran 1'!D21 -> 0 | I21: =H21*$C21 -> 0 | J21: =H21*$D21 -> 0 | K21: ='Setoran 1'!E21 -> 0 | L21: =K21*$C21 -> 0 | M21: =K21*$D21 -> 0 | N21: ='Setoran 1'!F21 -> 0 | O21: =N21*$C21 -> 0 | P21: =N21*$D21 -> 0 | Q21: ='Setoran 1'!G21 -> 0 | R21: =Q21*$C21 -> 0 | S21: =Q21*$D21 -> 0 | T21: ='Setoran 1'!H21 -> 0 | U21: =T21*$C21 -> 0 | V21: =T21*$D21 -> 0 | W21: ='Setoran 1'!I21 -> 0 | X21: =W21*$C21 -> 0 | Y21: =W21*$D21 -> 0 | Z21: ='Setoran 1'!J21 -> 0 | AA21: =Z21*$C21 -> 0 | AB21: =Z21*$D21 -> 0 | AC21: ='Setoran 1'!K21 -> 0 | AD21: =AC21*$C21 -> 0 | AE21: =AC21*$D21 -> 0 | AF21: ='Setoran 1'!L21 -> 0 | AG21: =AF21*$C21 -> 0 | AH21: =AF21*$D21 -> 0 | AI21: ='Setoran 1'!M21 -> 0 | AJ21: =AI21*$C21 -> 0 | AK21: =AI21*$D21 -> 0 | AL21: ='Setoran 1'!N21 -> 0 | AM21: =AL21*$C21 -> 0 | AN21: =AL21*$D21 -> 0 | AO21: ='Setoran 1'!O21 -> 0 | AP21: =AO21*$C21 -> 0 | AQ21: =AO21*$D21 -> 0 | AR21: ='Setoran 1'!P21 -> 0 | AS21: =AR21*$C21 -> 0 | AT21: =AR21*$D21 -> 0 | AU21: ='Setoran 1'!Q21 -> 0 | AV21: =AU21*$C21 -> 0 | AW21: =AU21*$D21 -> 0 | AX21: =SUM(E21,H21,K21,N21,Q21,T21,W21,Z21,AC21,AF21,AI21,AL21,AO21,AR21,AU21) -> 0 | AY21: =SUM(F21,I21,L21,O21,R21,U21,X21,AA21,AD21,,AG21,AJ21,AM21,AP21,AS21,AV21) -> 0 | AZ21: =SUM(G21,J21,M21,P21,S21,V21,Y21,AB21,AE21,AH21,AK21,AN21,AQ21,AT21,AW21) -> 0 | BA21: =AZ21-AY21 -> 0
A22: 7 | B22: PP Emberan Campur | C22: ='Data '!C21 -> 900 | D22: ='Data '!D21 -> 1000 | E22: ='Setoran 1'!C22 -> 0 | F22: =E22*C22 -> 0 | G22: =E22*D22 -> 0 | H22: ='Setoran 1'!D22 -> 0 | I22: =H22*$C22 -> 0 | J22: =H22*$D22 -> 0 | K22: ='Setoran 1'!E22 -> 0 | L22: =K22*$C22 -> 0 | M22: =K22*$D22 -> 0 | N22: ='Setoran 1'!F22 -> 0 | O22: =N22*$C22 -> 0 | P22: =N22*$D22 -> 0 | Q22: ='Setoran 1'!G22 -> 0 | R22: =Q22*$C22 -> 0 | S22: =Q22*$D22 -> 0 | T22: ='Setoran 1'!H22 -> 3.84 | U22: =T22*$C22 -> 3456 | V22: =T22*$D22 -> 3840 | W22: ='Setoran 1'!I22 -> 0 | X22: =W22*$C22 -> 0 | Y22: =W22*$D22 -> 0 | Z22: ='Setoran 1'!J22 -> 0 | AA22: =Z22*$C22 -> 0 | AB22: =Z22*$D22 -> 0 | AC22: ='Setoran 1'!K22 -> 0 | AD22: =AC22*$C22 -> 0 | AE22: =AC22*$D22 -> 0 | AF22: ='Setoran 1'!L22 -> 0 | AG22: =AF22*$C22 -> 0 | AH22: =AF22*$D22 -> 0 | AI22: ='Setoran 1'!M22 -> 0 | AJ22: =AI22*$C22 -> 0 | AK22: =AI22*$D22 -> 0 | AL22: ='Setoran 1'!N22 -> 0 | AM22: =AL22*$C22 -> 0 | AN22: =AL22*$D22 -> 0 | AO22: ='Setoran 1'!O22 -> 0 | AP22: =AO22*$C22 -> 0 | AQ22: =AO22*$D22 -> 0 | AR22: ='Setoran 1'!P22 -> 0 | AS22: =AR22*$C22 -> 0 | AT22: =AR22*$D22 -> 0 | AU22: ='Setoran 1'!Q22 -> 0 | AV22: =AU22*$C22 -> 0 | AW22: =AU22*$D22 -> 0 | AX22: =SUM(E22,H22,K22,N22,Q22,T22,W22,Z22,AC22,AF22,AI22,AL22,AO22,AR22,AU22) -> 3.84 | AY22: =SUM(F22,I22,L22,O22,R22,U22,X22,AA22,AD22,,AG22,AJ22,AM22,AP22,AS22,AV22) -> 3456 | AZ22: =SUM(G22,J22,M22,P22,S22,V22,Y22,AB22,AE22,AH22,AK22,AN22,AQ22,AT22,AW22) -> 3840 | BA22: =AZ22-AY22 -> 384
A23: 8 | B23: PP Emberan warna | C23: ='Data '!C22 -> 900 | D23: ='Data '!D22 -> 1000 | E23: ='Setoran 1'!C23 -> 0 | F23: =E23*C23 -> 0 | G23: =E23*D23 -> 0 | H23: ='Setoran 1'!D23 -> 0 | I23: =H23*$C23 -> 0 | J23: =H23*$D23 -> 0 | K23: ='Setoran 1'!E23 -> 0 | L23: =K23*$C23 -> 0 | M23: =K23*$D23 -> 0 | N23: ='Setoran 1'!F23 -> 0.17 | O23: =N23*$C23 -> 153 | P23: =N23*$D23 -> 170 | Q23: ='Setoran 1'!G23 -> 0 | R23: =Q23*$C23 -> 0 | S23: =Q23*$D23 -> 0 | T23: ='Setoran 1'!H23 -> 0 | U23: =T23*$C23 -> 0 | V23: =T23*$D23 -> 0 | W23: ='Setoran 1'!I23 -> 0.7 | X23: =W23*$C23 -> 630 | Y23: =W23*$D23 -> 700 | Z23: ='Setoran 1'!J23 -> 0 | AA23: =Z23*$C23 -> 0 | AB23: =Z23*$D23 -> 0 | AC23: ='Setoran 1'!K23 -> 0 | AD23: =AC23*$C23 -> 0 | AE23: =AC23*$D23 -> 0 | AF23: ='Setoran 1'!L23 -> 0 | AG23: =AF23*$C23 -> 0 | AH23: =AF23*$D23 -> 0 | AI23: ='Setoran 1'!M23 -> 0 | AJ23: =AI23*$C23 -> 0 | AK23: =AI23*$D23 -> 0 | AL23: ='Setoran 1'!N23 -> 0 | AM23: =AL23*$C23 -> 0 | AN23: =AL23*$D23 -> 0 | AO23: ='Setoran 1'!O23 -> 0 | AP23: =AO23*$C23 -> 0 | AQ23: =AO23*$D23 -> 0 | AR23: ='Setoran 1'!P23 -> 0 | AS23: =AR23*$C23 -> 0 | AT23: =AR23*$D23 -> 0 | AU23: ='Setoran 1'!Q23 -> 0 | AV23: =AU23*$C23 -> 0 | AW23: =AU23*$D23 -> 0 | AX23: =SUM(E23,H23,K23,N23,Q23,T23,W23,Z23,AC23,AF23,AI23,AL23,AO23,AR23,AU23) -> 0.87 | AY23: =SUM(F23,I23,L23,O23,R23,U23,X23,AA23,AD23,,AG23,AJ23,AM23,AP23,AS23,AV23) -> 783 | AZ23: =SUM(G23,J23,M23,P23,S23,V23,Y23,AB23,AE23,AH23,AK23,AN23,AQ23,AT23,AW23) -> 870 | BA23: =AZ23-AY23 -> 87
A24: 9 | B24: PP Emberan Hitam | C24: ='Data '!C23 -> 900 | D24: ='Data '!D23 -> 1000 | E24: ='Setoran 1'!C24 -> 0 | F24: =E24*C24 -> 0 | G24: =E24*D24 -> 0 | H24: ='Setoran 1'!D24 -> 0 | I24: =H24*$C24 -> 0 | J24: =H24*$D24 -> 0 | K24: ='Setoran 1'!E24 -> 0 | L24: =K24*$C24 -> 0 | M24: =K24*$D24 -> 0 | N24: ='Setoran 1'!F24 -> 0 | O24: =N24*$C24 -> 0 | P24: =N24*$D24 -> 0 | Q24: ='Setoran 1'!G24 -> 0 | R24: =Q24*$C24 -> 0 | S24: =Q24*$D24 -> 0 | T24: ='Setoran 1'!H24 -> 0 | U24: =T24*$C24 -> 0 | V24: =T24*$D24 -> 0 | W24: ='Setoran 1'!I24 -> 0 | X24: =W24*$C24 -> 0 | Y24: =W24*$D24 -> 0 | Z24: ='Setoran 1'!J24 -> 0 | AA24: =Z24*$C24 -> 0 | AB24: =Z24*$D24 -> 0 | AC24: ='Setoran 1'!K24 -> 0 | AD24: =AC24*$C24 -> 0 | AE24: =AC24*$D24 -> 0 | AF24: ='Setoran 1'!L24 -> 0 | AG24: =AF24*$C24 -> 0 | AH24: =AF24*$D24 -> 0 | AI24: ='Setoran 1'!M24 -> 0 | AJ24: =AI24*$C24 -> 0 | AK24: =AI24*$D24 -> 0 | AL24: ='Setoran 1'!N24 -> 0 | AM24: =AL24*$C24 -> 0 | AN24: =AL24*$D24 -> 0 | AO24: ='Setoran 1'!O24 -> 0 | AP24: =AO24*$C24 -> 0 | AQ24: =AO24*$D24 -> 0 | AR24: ='Setoran 1'!P24 -> 0 | AS24: =AR24*$C24 -> 0 | AT24: =AR24*$D24 -> 0 | AU24: ='Setoran 1'!Q24 -> 0 | AV24: =AU24*$C24 -> 0 | AW24: =AU24*$D24 -> 0 | AX24: =SUM(E24,H24,K24,N24,Q24,T24,W24,Z24,AC24,AF24,AI24,AL24,AO24,AR24,AU24) -> 0 | AY24: =SUM(F24,I24,L24,O24,R24,U24,X24,AA24,AD24,,AG24,AJ24,AM24,AP24,AS24,AV24) -> 0 | AZ24: =SUM(G24,J24,M24,P24,S24,V24,Y24,AB24,AE24,AH24,AK24,AN24,AQ24,AT24,AW24) -> 0 | BA24: =AZ24-AY24 -> 0
A25: 10 | B25: PC Galon UTUH / BIJI | C25: ='Data '!C24 -> 1300 | D25: ='Data '!D24 -> 1500 | E25: ='Setoran 1'!C25 -> 0 | F25: =E25*C25 -> 0 | G25: =E25*D25 -> 0 | H25: ='Setoran 1'!D25 -> 0 | I25: =H25*$C25 -> 0 | J25: =H25*$D25 -> 0 | K25: ='Setoran 1'!E25 -> 0 | L25: =K25*$C25 -> 0 | M25: =K25*$D25 -> 0 | N25: ='Setoran 1'!F25 -> 0 | O25: =N25*$C25 -> 0 | P25: =N25*$D25 -> 0 | Q25: ='Setoran 1'!G25 -> 0 | R25: =Q25*$C25 -> 0 | S25: =Q25*$D25 -> 0 | T25: ='Setoran 1'!H25 -> 0 | U25: =T25*$C25 -> 0 | V25: =T25*$D25 -> 0 | W25: ='Setoran 1'!I25 -> 0 | X25: =W25*$C25 -> 0 | Y25: =W25*$D25 -> 0 | Z25: ='Setoran 1'!J25 -> 0 | AA25: =Z25*$C25 -> 0 | AB25: =Z25*$D25 -> 0 | AC25: ='Setoran 1'!K25 -> 0 | AD25: =AC25*$C25 -> 0 | AE25: =AC25*$D25 -> 0 | AF25: ='Setoran 1'!L25 -> 0 | AG25: =AF25*$C25 -> 0 | AH25: =AF25*$D25 -> 0 | AI25: ='Setoran 1'!M25 -> 0 | AJ25: =AI25*$C25 -> 0 | AK25: =AI25*$D25 -> 0 | AL25: ='Setoran 1'!N25 -> 0 | AM25: =AL25*$C25 -> 0 | AN25: =AL25*$D25 -> 0 | AO25: ='Setoran 1'!O25 -> 0 | AP25: =AO25*$C25 -> 0 | AQ25: =AO25*$D25 -> 0 | AR25: ='Setoran 1'!P25 -> 0 | AS25: =AR25*$C25 -> 0 | AT25: =AR25*$D25 -> 0 | AU25: ='Setoran 1'!Q25 -> 0 | AV25: =AU25*$C25 -> 0 | AW25: =AU25*$D25 -> 0 | AX25: =SUM(E25,H25,K25,N25,Q25,T25,W25,Z25,AC25,AF25,AI25,AL25,AO25,AR25,AU25) -> 0 | AY25: =SUM(F25,I25,L25,O25,R25,U25,X25,AA25,AD25,,AG25,AJ25,AM25,AP25,AS25,AV25) -> 0 | AZ25: =SUM(G25,J25,M25,P25,S25,V25,Y25,AB25,AE25,AH25,AK25,AN25,AQ25,AT25,AW25) -> 0 | BA25: =AZ25-AY25 -> 0
A26: 11 | B26: PC Galon PECAH / KG | C26: ='Data '!C25 -> 800 | D26: ='Data '!D25 -> 1000 | E26: ='Setoran 1'!C26 -> 0 | F26: =E26*C26 -> 0 | G26: =E26*D26 -> 0 | H26: ='Setoran 1'!D26 -> 0 | I26: =H26*$C26 -> 0 | J26: =H26*$D26 -> 0 | K26: ='Setoran 1'!E26 -> 0 | L26: =K26*$C26 -> 0 | M26: =K26*$D26 -> 0 | N26: ='Setoran 1'!F26 -> 0 | O26: =N26*$C26 -> 0 | P26: =N26*$D26 -> 0 | Q26: ='Setoran 1'!G26 -> 0 | R26: =Q26*$C26 -> 0 | S26: =Q26*$D26 -> 0 | T26: ='Setoran 1'!H26 -> 0 | U26: =T26*$C26 -> 0 | V26: =T26*$D26 -> 0 | W26: ='Setoran 1'!I26 -> 0 | X26: =W26*$C26 -> 0 | Y26: =W26*$D26 -> 0 | Z26: ='Setoran 1'!J26 -> 0 | AA26: =Z26*$C26 -> 0 | AB26: =Z26*$D26 -> 0 | AC26: ='Setoran 1'!K26 -> 0 | AD26: =AC26*$C26 -> 0 | AE26: =AC26*$D26 -> 0 | AF26: ='Setoran 1'!L26 -> 0 | AG26: =AF26*$C26 -> 0 | AH26: =AF26*$D26 -> 0 | AI26: ='Setoran 1'!M26 -> 0 | AJ26: =AI26*$C26 -> 0 | AK26: =AI26*$D26 -> 0 | AL26: ='Setoran 1'!N26 -> 0 | AM26: =AL26*$C26 -> 0 | AN26: =AL26*$D26 -> 0 | AO26: ='Setoran 1'!O26 -> 0 | AP26: =AO26*$C26 -> 0 | AQ26: =AO26*$D26 -> 0 | AR26: ='Setoran 1'!P26 -> 0 | AS26: =AR26*$C26 -> 0 | AT26: =AR26*$D26 -> 0 | AU26: ='Setoran 1'!Q26 -> 0 | AV26: =AU26*$C26 -> 0 | AW26: =AU26*$D26 -> 0 | AX26: =SUM(E26,H26,K26,N26,Q26,T26,W26,Z26,AC26,AF26,AI26,AL26,AO26,AR26,AU26) -> 0 | AY26: =SUM(F26,I26,L26,O26,R26,U26,X26,AA26,AD26,,AG26,AJ26,AM26,AP26,AS26,AV26) -> 0 | AZ26: =SUM(G26,J26,M26,P26,S26,V26,Y26,AB26,AE26,AH26,AK26,AN26,AQ26,AT26,AW26) -> 0 | BA26: =AZ26-AY26 -> 0
A27: GELASAN
A28: 1 | B28: Aqua Gelas Kotor | C28: ='Data '!C26 -> 1100 | D28: ='Data '!D26 -> 1200 | E28: ='Setoran 1'!C28 -> 0 | F28: =E28*C28 -> 0 | G28: =E28*D28 -> 0 | H28: ='Setoran 1'!D28 -> 0 | I28: =H28*$C28 -> 0 | J28: =H28*$D28 -> 0 | K28: ='Setoran 1'!E28 -> 0 | L28: =K28*$C28 -> 0 | M28: =K28*$D28 -> 0 | N28: ='Setoran 1'!F28 -> 0 | O28: =N28*$C28 -> 0 | P28: =N28*$D28 -> 0 | Q28: ='Setoran 1'!G28 -> 0 | R28: =Q28*$C28 -> 0 | S28: =Q28*$D28 -> 0 | T28: ='Setoran 1'!H28 -> 0 | U28: =T28*$C28 -> 0 | V28: =T28*$D28 -> 0 | W28: ='Setoran 1'!I28 -> 0 | X28: =W28*$C28 -> 0 | Y28: =W28*$D28 -> 0 | Z28: ='Setoran 1'!J28 -> 0 | AA28: =Z28*$C28 -> 0 | AB28: =Z28*$D28 -> 0 | AC28: ='Setoran 1'!K28 -> 0 | AD28: =AC28*$C28 -> 0 | AE28: =AC28*$D28 -> 0 | AF28: ='Setoran 1'!L28 -> 0 | AG28: =AF28*$C28 -> 0 | AH28: =AF28*$D28 -> 0 | AI28: ='Setoran 1'!M28 -> 0 | AJ28: =AI28*$C28 -> 0 | AK28: =AI28*$D28 -> 0 | AL28: ='Setoran 1'!N28 -> 0 | AM28: =AL28*$C28 -> 0 | AN28: =AL28*$D28 -> 0 | AO28: ='Setoran 1'!O28 -> 0 | AP28: =AO28*$C28 -> 0 | AQ28: =AO28*$D28 -> 0 | AR28: ='Setoran 1'!P28 -> 0 | AS28: =AR28*$C28 -> 0 | AT28: =AR28*$D28 -> 0 | AU28: ='Setoran 1'!Q28 -> 0 | AV28: =AU28*$C28 -> 0 | AW28: =AU28*$D28 -> 0 | AX28: =SUM(E28,H28,K28,N28,Q28,T28,W28,Z28,AC28,AF28,AI28,AL28,AO28,AR28,AU28) -> 0 | AY28: =SUM(F28,I28,L28,O28,R28,U28,X28,AA28,AD28,,AG28,AJ28,AM28,AP28,AS28,AV28) -> 0 | AZ28: =SUM(G28,J28,M28,P28,S28,V28,Y28,AB28,AE28,AH28,AK28,AN28,AQ28,AT28,AW28) -> 0 | BA28: =AZ28-AY28 -> 0
A29: 2 | B29: Aqua Gelas Bersih | C29: ='Data '!C27 -> 1900 | D29: ='Data '!D27 -> 2000 | E29: ='Setoran 1'!C29 -> 0 | F29: =E29*C29 -> 0 | G29: =E29*D29 -> 0 | H29: ='Setoran 1'!D29 -> 0 | I29: =H29*$C29 -> 0 | J29: =H29*$D29 -> 0 | K29: ='Setoran 1'!E29 -> 0 | L29: =K29*$C29 -> 0 | M29: =K29*$D29 -> 0 | N29: ='Setoran 1'!F29 -> 0 | O29: =N29*$C29 -> 0 | P29: =N29*$D29 -> 0 | Q29: ='Setoran 1'!G29 -> 0 | R29: =Q29*$C29 -> 0 | S29: =Q29*$D29 -> 0 | T29: ='Setoran 1'!H29 -> 0 | U29: =T29*$C29 -> 0 | V29: =T29*$D29 -> 0 | W29: ='Setoran 1'!I29 -> 0 | X29: =W29*$C29 -> 0 | Y29: =W29*$D29 -> 0 | Z29: ='Setoran 1'!J29 -> 0 | AA29: =Z29*$C29 -> 0 | AB29: =Z29*$D29 -> 0 | AC29: ='Setoran 1'!K29 -> 0 | AD29: =AC29*$C29 -> 0 | AE29: =AC29*$D29 -> 0 | AF29: ='Setoran 1'!L29 -> 0 | AG29: =AF29*$C29 -> 0 | AH29: =AF29*$D29 -> 0 | AI29: ='Setoran 1'!M29 -> 0 | AJ29: =AI29*$C29 -> 0 | AK29: =AI29*$D29 -> 0 | AL29: ='Setoran 1'!N29 -> 0 | AM29: =AL29*$C29 -> 0 | AN29: =AL29*$D29 -> 0 | AO29: ='Setoran 1'!O29 -> 0 | AP29: =AO29*$C29 -> 0 | AQ29: =AO29*$D29 -> 0 | AR29: ='Setoran 1'!P29 -> 0 | AS29: =AR29*$C29 -> 0 | AT29: =AR29*$D29 -> 0 | AU29: ='Setoran 1'!Q29 -> 0 | AV29: =AU29*$C29 -> 0 | AW29: =AU29*$D29 -> 0 | AX29: =SUM(E29,H29,K29,N29,Q29,T29,W29,Z29,AC29,AF29,AI29,AL29,AO29,AR29,AU29) -> 0 | AY29: =SUM(F29,I29,L29,O29,R29,U29,X29,AA29,AD29,,AG29,AJ29,AM29,AP29,AS29,AV29) -> 0 | AZ29: =SUM(G29,J29,M29,P29,S29,V29,Y29,AB29,AE29,AH29,AK29,AN29,AQ29,AT29,AW29) -> 0 | BA29: =AZ29-AY29 -> 0
A30: 3 | B30: Mountea/Sablon | C30: ='Data '!C28 -> 900 | D30: ='Data '!D28 -> 1000 | E30: ='Setoran 1'!C30 -> 0 | F30: =E30*C30 -> 0 | G30: =E30*D30 -> 0 | H30: ='Setoran 1'!D30 -> 0 | I30: =H30*$C30 -> 0 | J30: =H30*$D30 -> 0 | K30: ='Setoran 1'!E30 -> 0 | L30: =K30*$C30 -> 0 | M30: =K30*$D30 -> 0 | N30: ='Setoran 1'!F30 -> 0 | O30: =N30*$C30 -> 0 | P30: =N30*$D30 -> 0 | Q30: ='Setoran 1'!G30 -> 0 | R30: =Q30*$C30 -> 0 | S30: =Q30*$D30 -> 0 | T30: ='Setoran 1'!H30 -> 0 | U30: =T30*$C30 -> 0 | V30: =T30*$D30 -> 0 | W30: ='Setoran 1'!I30 -> 0 | X30: =W30*$C30 -> 0 | Y30: =W30*$D30 -> 0 | Z30: ='Setoran 1'!J30 -> 0 | AA30: =Z30*$C30 -> 0 | AB30: =Z30*$D30 -> 0 | AC30: ='Setoran 1'!K30 -> 0 | AD30: =AC30*$C30 -> 0 | AE30: =AC30*$D30 -> 0 | AF30: ='Setoran 1'!L30 -> 0 | AG30: =AF30*$C30 -> 0 | AH30: =AF30*$D30 -> 0 | AI30: ='Setoran 1'!M30 -> 0 | AJ30: =AI30*$C30 -> 0 | AK30: =AI30*$D30 -> 0 | AL30: ='Setoran 1'!N30 -> 0 | AM30: =AL30*$C30 -> 0 | AN30: =AL30*$D30 -> 0 | AO30: ='Setoran 1'!O30 -> 0 | AP30: =AO30*$C30 -> 0 | AQ30: =AO30*$D30 -> 0 | AR30: ='Setoran 1'!P30 -> 0 | AS30: =AR30*$C30 -> 0 | AT30: =AR30*$D30 -> 0 | AU30: ='Setoran 1'!Q30 -> 0 | AV30: =AU30*$C30 -> 0 | AW30: =AU30*$D30 -> 0 | AX30: =SUM(E30,H30,K30,N30,Q30,T30,W30,Z30,AC30,AF30,AI30,AL30,AO30,AR30,AU30) -> 0 | AY30: =SUM(F30,I30,L30,O30,R30,U30,X30,AA30,AD30,,AG30,AJ30,AM30,AP30,AS30,AV30) -> 0 | AZ30: =SUM(G30,J30,M30,P30,S30,V30,Y30,AB30,AE30,AH30,AK30,AN30,AQ30,AT30,AW30) -> 0 | BA30: =AZ30-AY30 -> 0
A31: PLASTIK FLEKSIBEL / LEMBARAN
A32: 1 | B32: Plastik Bening PE & PP | C32: ='Data '!C29 -> 400 | D32: ='Data '!D29 -> 500 | E32: ='Setoran 1'!C32 -> 0 | F32: =E32*C32 -> 0 | G32: =E32*D32 -> 0 | H32: ='Setoran 1'!D32 -> 0 | I32: =H32*$C32 -> 0 | J32: =H32*$D32 -> 0 | K32: ='Setoran 1'!E32 -> 0 | L32: =K32*$C32 -> 0 | M32: =K32*$D32 -> 0 | N32: ='Setoran 1'!F32 -> 0 | O32: =N32*$C32 -> 0 | P32: =N32*$D32 -> 0 | Q32: ='Setoran 1'!G32 -> 0 | R32: =Q32*$C32 -> 0 | S32: =Q32*$D32 -> 0 | T32: ='Setoran 1'!H32 -> 1.07 | U32: =T32*$C32 -> 428 | V32: =T32*$D32 -> 535 | W32: ='Setoran 1'!I32 -> 0 | X32: =W32*$C32 -> 0 | Y32: =W32*$D32 -> 0 | Z32: ='Setoran 1'!J32 -> 0 | AA32: =Z32*$C32 -> 0 | AB32: =Z32*$D32 -> 0 | AC32: ='Setoran 1'!K32 -> 3.5 | AD32: =AC32*$C32 -> 1400 | AE32: =AC32*$D32 -> 1750 | AF32: ='Setoran 1'!L32 -> 0 | AG32: =AF32*$C32 -> 0 | AH32: =AF32*$D32 -> 0 | AI32: ='Setoran 1'!M32 -> 0 | AJ32: =AI32*$C32 -> 0 | AK32: =AI32*$D32 -> 0 | AL32: ='Setoran 1'!N32 -> 0 | AM32: =AL32*$C32 -> 0 | AN32: =AL32*$D32 -> 0 | AO32: ='Setoran 1'!O32 -> 0 | AP32: =AO32*$C32 -> 0 | AQ32: =AO32*$D32 -> 0 | AR32: ='Setoran 1'!P32 -> 0 | AS32: =AR32*$C32 -> 0 | AT32: =AR32*$D32 -> 0 | AU32: ='Setoran 1'!Q32 -> 0 | AV32: =AU32*$C32 -> 0 | AW32: =AU32*$D32 -> 0 | AX32: =SUM(E32,H32,K32,N32,Q32,T32,W32,Z32,AC32,AF32,AI32,AL32,AO32,AR32,AU32) -> 4.57 | AY32: =SUM(F32,I32,L32,O32,R32,U32,X32,AA32,AD32,,AG32,AJ32,AM32,AP32,AS32,AV32) -> 1828 | AZ32: =SUM(G32,J32,M32,P32,S32,V32,Y32,AB32,AE32,AH32,AK32,AN32,AQ32,AT32,AW32) -> 2285 | BA32: =AZ32-AY32 -> 457
A33: 2 | B33: HD Kresek | C33: ='Data '!C30 -> 50 | D33: ='Data '!D30 -> 100 | E33: ='Setoran 1'!C33 -> 0 | F33: =E33*C33 -> 0 | G33: =E33*D33 -> 0 | H33: ='Setoran 1'!D33 -> 1.2 | I33: =H33*$C33 -> 60 | J33: =H33*$D33 -> 120 | K33: ='Setoran 1'!E33 -> 0 | L33: =K33*$C33 -> 0 | M33: =K33*$D33 -> 0 | N33: ='Setoran 1'!F33 -> 0 | O33: =N33*$C33 -> 0 | P33: =N33*$D33 -> 0 | Q33: ='Setoran 1'!G33 -> 4.4 | R33: =Q33*$C33 -> 220 | S33: =Q33*$D33 -> 440 | T33: ='Setoran 1'!H33 -> 0.62 | U33: =T33*$C33 -> 31 | V33: =T33*$D33 -> 62 | W33: ='Setoran 1'!I33 -> 0 | X33: =W33*$C33 -> 0 | Y33: =W33*$D33 -> 0 | Z33: ='Setoran 1'!J33 -> 0 | AA33: =Z33*$C33 -> 0 | AB33: =Z33*$D33 -> 0 | AC33: ='Setoran 1'!K33 -> 0 | AD33: =AC33*$C33 -> 0 | AE33: =AC33*$D33 -> 0 | AF33: ='Setoran 1'!L33 -> 0 | AG33: =AF33*$C33 -> 0 | AH33: =AF33*$D33 -> 0 | AI33: ='Setoran 1'!M33 -> 0 | AJ33: =AI33*$C33 -> 0 | AK33: =AI33*$D33 -> 0 | AL33: ='Setoran 1'!N33 -> 0 | AM33: =AL33*$C33 -> 0 | AN33: =AL33*$D33 -> 0 | AO33: ='Setoran 1'!O33 -> 0 | AP33: =AO33*$C33 -> 0 | AQ33: =AO33*$D33 -> 0 | AR33: ='Setoran 1'!P33 -> 0 | AS33: =AR33*$C33 -> 0 | AT33: =AR33*$D33 -> 0 | AU33: ='Setoran 1'!Q33 -> 0 | AV33: =AU33*$C33 -> 0 | AW33: =AU33*$D33 -> 0 | AX33: =SUM(E33,H33,K33,N33,Q33,T33,W33,Z33,AC33,AF33,AI33,AL33,AO33,AR33,AU33) -> 6.22 | AY33: =SUM(F33,I33,L33,O33,R33,U33,X33,AA33,AD33,,AG33,AJ33,AM33,AP33,AS33,AV33) -> 311 | AZ33: =SUM(G33,J33,M33,P33,S33,V33,Y33,AB33,AE33,AH33,AK33,AN33,AQ33,AT33,AW33) -> 622 | BA33: =AZ33-AY33 -> 311
A34: 3 | B34: Kresek Campur | C34: ='Data '!C31 -> 50 | D34: ='Data '!D31 -> 100 | E34: ='Setoran 1'!C34 -> 4.2 | F34: =E34*C34 -> 210 | G34: =E34*D34 -> 420 | H34: ='Setoran 1'!D34 -> 0 | I34: =H34*$C34 -> 0 | J34: =H34*$D34 -> 0 | K34: ='Setoran 1'!E34 -> 0 | L34: =K34*$C34 -> 0 | M34: =K34*$D34 -> 0 | N34: ='Setoran 1'!F34 -> 0.53 | O34: =N34*$C34 -> 26.5 | P34: =N34*$D34 -> 53 | Q34: ='Setoran 1'!G34 -> 0 | R34: =Q34*$C34 -> 0 | S34: =Q34*$D34 -> 0 | T34: ='Setoran 1'!H34 -> 0.88 | U34: =T34*$C34 -> 44 | V34: =T34*$D34 -> 88 | W34: ='Setoran 1'!I34 -> 7.22 | X34: =W34*$C34 -> 361 | Y34: =W34*$D34 -> 722 | Z34: ='Setoran 1'!J34 -> 0 | AA34: =Z34*$C34 -> 0 | AB34: =Z34*$D34 -> 0 | AC34: ='Setoran 1'!K34 -> 2.93 | AD34: =AC34*$C34 -> 146.5 | AE34: =AC34*$D34 -> 293 | AF34: ='Setoran 1'!L34 -> 0.57 | AG34: =AF34*$C34 -> 28.5 | AH34: =AF34*$D34 -> 57 | AI34: ='Setoran 1'!M34 -> 0 | AJ34: =AI34*$C34 -> 0 | AK34: =AI34*$D34 -> 0 | AL34: ='Setoran 1'!N34 -> 0 | AM34: =AL34*$C34 -> 0 | AN34: =AL34*$D34 -> 0 | AO34: ='Setoran 1'!O34 -> 0 | AP34: =AO34*$C34 -> 0 | AQ34: =AO34*$D34 -> 0 | AR34: ='Setoran 1'!P34 -> 0 | AS34: =AR34*$C34 -> 0 | AT34: =AR34*$D34 -> 0 | AU34: ='Setoran 1'!Q34 -> 0 | AV34: =AU34*$C34 -> 0 | AW34: =AU34*$D34 -> 0 | AX34: =SUM(E34,H34,K34,N34,Q34,T34,W34,Z34,AC34,AF34,AI34,AL34,AO34,AR34,AU34) -> 16.33 | AY34: =SUM(F34,I34,L34,O34,R34,U34,X34,AA34,AD34,,AG34,AJ34,AM34,AP34,AS34,AV34) -> 816.5 | AZ34: =SUM(G34,J34,M34,P34,S34,V34,Y34,AB34,AE34,AH34,AK34,AN34,AQ34,AT34,AW34) -> 1633 | BA34: =AZ34-AY34 -> 816.5
A35: 4 | B35: LLDPE Pouch | C35: ='Data '!C32 -> 40 | D35: ='Data '!D32 -> 50 | E35: ='Setoran 1'!C35 -> 0 | F35: =E35*C35 -> 0 | G35: =E35*D35 -> 0 | H35: ='Setoran 1'!D35 -> 0 | I35: =H35*$C35 -> 0 | J35: =H35*$D35 -> 0 | K35: ='Setoran 1'!E35 -> 0 | L35: =K35*$C35 -> 0 | M35: =K35*$D35 -> 0 | N35: ='Setoran 1'!F35 -> 0 | O35: =N35*$C35 -> 0 | P35: =N35*$D35 -> 0 | Q35: ='Setoran 1'!G35 -> 0 | R35: =Q35*$C35 -> 0 | S35: =Q35*$D35 -> 0 | T35: ='Setoran 1'!H35 -> 0 | U35: =T35*$C35 -> 0 | V35: =T35*$D35 -> 0 | W35: ='Setoran 1'!I35 -> 0 | X35: =W35*$C35 -> 0 | Y35: =W35*$D35 -> 0 | Z35: ='Setoran 1'!J35 -> 0 | AA35: =Z35*$C35 -> 0 | AB35: =Z35*$D35 -> 0 | AC35: ='Setoran 1'!K35 -> 0 | AD35: =AC35*$C35 -> 0 | AE35: =AC35*$D35 -> 0 | AF35: ='Setoran 1'!L35 -> 0 | AG35: =AF35*$C35 -> 0 | AH35: =AF35*$D35 -> 0 | AI35: ='Setoran 1'!M35 -> 0 | AJ35: =AI35*$C35 -> 0 | AK35: =AI35*$D35 -> 0 | AL35: ='Setoran 1'!N35 -> 0 | AM35: =AL35*$C35 -> 0 | AN35: =AL35*$D35 -> 0 | AO35: ='Setoran 1'!O35 -> 0 | AP35: =AO35*$C35 -> 0 | AQ35: =AO35*$D35 -> 0 | AR35: ='Setoran 1'!P35 -> 0 | AS35: =AR35*$C35 -> 0 | AT35: =AR35*$D35 -> 0 | AU35: ='Setoran 1'!Q35 -> 0 | AV35: =AU35*$C35 -> 0 | AW35: =AU35*$D35 -> 0 | AX35: =SUM(E35,H35,K35,N35,Q35,T35,W35,Z35,AC35,AF35,AI35,AL35,AO35,AR35,AU35) -> 0 | AY35: =SUM(F35,I35,L35,O35,R35,U35,X35,AA35,AD35,,AG35,AJ35,AM35,AP35,AS35,AV35) -> 0 | AZ35: =SUM(G35,J35,M35,P35,S35,V35,Y35,AB35,AE35,AH35,AK35,AN35,AQ35,AT35,AW35) -> 0 | BA35: =AZ35-AY35 -> 0
A36: 5 | B36: PP Sablon lembaran | C36: ='Data '!C33 -> 40 | D36: ='Data '!D33 -> 50 | E36: ='Setoran 1'!C36 -> 0 | F36: =E36*C36 -> 0 | G36: =E36*D36 -> 0 | H36: ='Setoran 1'!D36 -> 0 | I36: =H36*$C36 -> 0 | J36: =H36*$D36 -> 0 | K36: ='Setoran 1'!E36 -> 0 | L36: =K36*$C36 -> 0 | M36: =K36*$D36 -> 0 | N36: ='Setoran 1'!F36 -> 0 | O36: =N36*$C36 -> 0 | P36: =N36*$D36 -> 0 | Q36: ='Setoran 1'!G36 -> 0 | R36: =Q36*$C36 -> 0 | S36: =Q36*$D36 -> 0 | T36: ='Setoran 1'!H36 -> 0 | U36: =T36*$C36 -> 0 | V36: =T36*$D36 -> 0 | W36: ='Setoran 1'!I36 -> 0 | X36: =W36*$C36 -> 0 | Y36: =W36*$D36 -> 0 | Z36: ='Setoran 1'!J36 -> 0 | AA36: =Z36*$C36 -> 0 | AB36: =Z36*$D36 -> 0 | AC36: ='Setoran 1'!K36 -> 0 | AD36: =AC36*$C36 -> 0 | AE36: =AC36*$D36 -> 0 | AF36: ='Setoran 1'!L36 -> 0 | AG36: =AF36*$C36 -> 0 | AH36: =AF36*$D36 -> 0 | AI36: ='Setoran 1'!M36 -> 0 | AJ36: =AI36*$C36 -> 0 | AK36: =AI36*$D36 -> 0 | AL36: ='Setoran 1'!N36 -> 0 | AM36: =AL36*$C36 -> 0 | AN36: =AL36*$D36 -> 0 | AO36: ='Setoran 1'!O36 -> 0 | AP36: =AO36*$C36 -> 0 | AQ36: =AO36*$D36 -> 0 | AR36: ='Setoran 1'!P36 -> 0 | AS36: =AR36*$C36 -> 0 | AT36: =AR36*$D36 -> 0 | AU36: ='Setoran 1'!Q36 -> 0 | AV36: =AU36*$C36 -> 0 | AW36: =AU36*$D36 -> 0 | AX36: =SUM(E36,H36,K36,N36,Q36,T36,W36,Z36,AC36,AF36,AI36,AL36,AO36,AR36,AU36) -> 0 | AY36: =SUM(F36,I36,L36,O36,R36,U36,X36,AA36,AD36,,AG36,AJ36,AM36,AP36,AS36,AV36) -> 0 | AZ36: =SUM(G36,J36,M36,P36,S36,V36,Y36,AB36,AE36,AH36,AK36,AN36,AQ36,AT36,AW36) -> 0 | BA36: =AZ36-AY36 -> 0
A37: 6 | B37: Multi Layer | C37: ='Data '!C34 -> 250 | D37: ='Data '!D34 -> 300 | E37: ='Setoran 1'!C37 -> 0 | F37: =E37*C37 -> 0 | G37: =E37*D37 -> 0 | H37: ='Setoran 1'!D37 -> 0 | I37: =H37*$C37 -> 0 | J37: =H37*$D37 -> 0 | K37: ='Setoran 1'!E37 -> 0 | L37: =K37*$C37 -> 0 | M37: =K37*$D37 -> 0 | N37: ='Setoran 1'!F37 -> 0.25 | O37: =N37*$C37 -> 62.5 | P37: =N37*$D37 -> 75 | Q37: ='Setoran 1'!G37 -> 0 | R37: =Q37*$C37 -> 0 | S37: =Q37*$D37 -> 0 | T37: ='Setoran 1'!H37 -> 0.77 | U37: =T37*$C37 -> 192.5 | V37: =T37*$D37 -> 231 | W37: ='Setoran 1'!I37 -> 0.58 | X37: =W37*$C37 -> 145 | Y37: =W37*$D37 -> 174 | Z37: ='Setoran 1'!J37 -> 0 | AA37: =Z37*$C37 -> 0 | AB37: =Z37*$D37 -> 0 | AC37: ='Setoran 1'!K37 -> 0.75 | AD37: =AC37*$C37 -> 187.5 | AE37: =AC37*$D37 -> 225 | AF37: ='Setoran 1'!L37 -> 0 | AG37: =AF37*$C37 -> 0 | AH37: =AF37*$D37 -> 0 | AI37: ='Setoran 1'!M37 -> 0 | AJ37: =AI37*$C37 -> 0 | AK37: =AI37*$D37 -> 0 | AL37: ='Setoran 1'!N37 -> 0 | AM37: =AL37*$C37 -> 0 | AN37: =AL37*$D37 -> 0 | AO37: ='Setoran 1'!O37 -> 0 | AP37: =AO37*$C37 -> 0 | AQ37: =AO37*$D37 -> 0 | AR37: ='Setoran 1'!P37 -> 0 | AS37: =AR37*$C37 -> 0 | AT37: =AR37*$D37 -> 0 | AU37: ='Setoran 1'!Q37 -> 0 | AV37: =AU37*$C37 -> 0 | AW37: =AU37*$D37 -> 0 | AX37: =SUM(E37,H37,K37,N37,Q37,T37,W37,Z37,AC37,AF37,AI37,AL37,AO37,AR37,AU37) -> 2.35 | AY37: =SUM(F37,I37,L37,O37,R37,U37,X37,AA37,AD37,,AG37,AJ37,AM37,AP37,AS37,AV37) -> 587.5 | AZ37: =SUM(G37,J37,M37,P37,S37,V37,Y37,AB37,AE37,AH37,AK37,AN37,AQ37,AT37,AW37) -> 705 | BA37: =AZ37-AY37 -> 117.5
A38: KERASAN
A39: 1 | B39: Kerasan / PS/ ABS | C39: ='Data '!C35 -> 75 | D39: ='Data '!D35 -> 100 | E39: ='Setoran 1'!C39 -> 7.6 | F39: =E39*C39 -> 570 | G39: =E39*D39 -> 760 | H39: ='Setoran 1'!D39 -> 0 | I39: =H39*$C39 -> 0 | J39: =H39*$D39 -> 0 | K39: ='Setoran 1'!E39 -> 0 | L39: =K39*$C39 -> 0 | M39: =K39*$D39 -> 0 | N39: ='Setoran 1'!F39 -> 0 | O39: =N39*$C39 -> 0 | P39: =N39*$D39 -> 0 | Q39: ='Setoran 1'!G39 -> 1.1 | R39: =Q39*$C39 -> 82.5 | S39: =Q39*$D39 -> 110 | T39: ='Setoran 1'!H39 -> 1.37 | U39: =T39*$C39 -> 102.75 | V39: =T39*$D39 -> 137 | W39: ='Setoran 1'!I39 -> 0 | X39: =W39*$C39 -> 0 | Y39: =W39*$D39 -> 0 | Z39: ='Setoran 1'!J39 -> 0 | AA39: =Z39*$C39 -> 0 | AB39: =Z39*$D39 -> 0 | AC39: ='Setoran 1'!K39 -> 4.32 | AD39: =AC39*$C39 -> 324 | AE39: =AC39*$D39 -> 432 | AF39: ='Setoran 1'!L39 -> 0.22 | AG39: =AF39*$C39 -> 16.5 | AH39: =AF39*$D39 -> 22 | AI39: ='Setoran 1'!M39 -> 0 | AJ39: =AI39*$C39 -> 0 | AK39: =AI39*$D39 -> 0 | AL39: ='Setoran 1'!N39 -> 0 | AM39: =AL39*$C39 -> 0 | AN39: =AL39*$D39 -> 0 | AO39: ='Setoran 1'!O39 -> 0 | AP39: =AO39*$C39 -> 0 | AQ39: =AO39*$D39 -> 0 | AR39: ='Setoran 1'!P39 -> 0 | AS39: =AR39*$C39 -> 0 | AT39: =AR39*$D39 -> 0 | AU39: ='Setoran 1'!Q39 -> 0 | AV39: =AU39*$C39 -> 0 | AW39: =AU39*$D39 -> 0 | AX39: =SUM(E39,H39,K39,N39,Q39,T39,W39,Z39,AC39,AF39,AI39,AL39,AO39,AR39,AU39) -> 14.61 | AY39: =SUM(F39,I39,L39,O39,R39,U39,X39,AA39,AD39,,AG39,AJ39,AM39,AP39,AS39,AV39) -> 1095.75 | AZ39: =SUM(G39,J39,M39,P39,S39,V39,Y39,AB39,AE39,AH39,AK39,AN39,AQ39,AT39,AW39) -> 1461 | BA39: =AZ39-AY39 -> 365.25
A40: 2 | B40: PVC | C40: ='Data '!C36 -> 50 | D40: ='Data '!D36 -> 100 | E40: ='Setoran 1'!C40 -> 0 | F40: =E40*C40 -> 0 | G40: =E40*D40 -> 0 | H40: ='Setoran 1'!D40 -> 0 | I40: =H40*$C40 -> 0 | J40: =H40*$D40 -> 0 | K40: ='Setoran 1'!E40 -> 0 | L40: =K40*$C40 -> 0 | M40: =K40*$D40 -> 0 | N40: ='Setoran 1'!F40 -> 0 | O40: =N40*$C40 -> 0 | P40: =N40*$D40 -> 0 | Q40: ='Setoran 1'!G40 -> 0 | R40: =Q40*$C40 -> 0 | S40: =Q40*$D40 -> 0 | T40: ='Setoran 1'!H40 -> 0 | U40: =T40*$C40 -> 0 | V40: =T40*$D40 -> 0 | W40: ='Setoran 1'!I40 -> 0 | X40: =W40*$C40 -> 0 | Y40: =W40*$D40 -> 0 | Z40: ='Setoran 1'!J40 -> 0 | AA40: =Z40*$C40 -> 0 | AB40: =Z40*$D40 -> 0 | AC40: ='Setoran 1'!K40 -> 0 | AD40: =AC40*$C40 -> 0 | AE40: =AC40*$D40 -> 0 | AF40: ='Setoran 1'!L40 -> 0 | AG40: =AF40*$C40 -> 0 | AH40: =AF40*$D40 -> 0 | AI40: ='Setoran 1'!M40 -> 0 | AJ40: =AI40*$C40 -> 0 | AK40: =AI40*$D40 -> 0 | AL40: ='Setoran 1'!N40 -> 0 | AM40: =AL40*$C40 -> 0 | AN40: =AL40*$D40 -> 0 | AO40: ='Setoran 1'!O40 -> 0 | AP40: =AO40*$C40 -> 0 | AQ40: =AO40*$D40 -> 0 | AR40: ='Setoran 1'!P40 -> 0 | AS40: =AR40*$C40 -> 0 | AT40: =AR40*$D40 -> 0 | AU40: ='Setoran 1'!Q40 -> 0 | AV40: =AU40*$C40 -> 0 | AW40: =AU40*$D40 -> 0 | AX40: =SUM(E40,H40,K40,N40,Q40,T40,W40,Z40,AC40,AF40,AI40,AL40,AO40,AR40,AU40) -> 0 | AY40: =SUM(F40,I40,L40,O40,R40,U40,X40,AA40,AD40,,AG40,AJ40,AM40,AP40,AS40,AV40) -> 0 | AZ40: =SUM(G40,J40,M40,P40,S40,V40,Y40,AB40,AE40,AH40,AK40,AN40,AQ40,AT40,AW40) -> 0 | BA40: =AZ40-AY40 -> 0
A41: KERTAS
...

Sheet Rekap 2
A1: ='Setoran 1'!A1:R1 -> REKAP JUAL BELI SAMPAH NASABAH BALI ARUM (BALI WASTE CYCLE)
A2: ='Data '!A2 -> TANGGAL : 8 Agustus2026
A4: NO | B4: JENIS | C4: HARGA BELI | D4: HARGA JUAL | E4: NOMOR INDUK NASABAH | AX4: TOTAL | AY4: TOTAL BELI | AZ4: TOTAL JUAL | BA4: MARGIN
E5: ='Setoran 2'!C6 -> 0 | H5: ='Setoran 2'!D6 -> 0 | K5: ='Setoran 2'!E6 -> 0 | N5: ='Setoran 2'!F6 -> 0 | Q5: ='Setoran 2'!G6 -> 0 | T5: ='Setoran 2'!H6 -> 0 | W5: ='Setoran 2'!I6 -> 0 | Z5: ='Setoran 2'!J6 -> 0 | AC5: ='Setoran 2'!K6 -> 0 | AF5: ='Setoran 2'!L6 -> 0 | AI5: ='Setoran 2'!M6 -> 0 | AL5: ='Setoran 2'!N6 -> 0 | AO5: ='Setoran 2'!O6 -> 0 | AR5: ='Setoran 2'!P6 -> 0 | AU5: ='Setoran 2'!Q6 -> 0
E6: Berat Setoran | F6: Total Harga Beli | G6: Total Harga Jual | H6: Berat Setoran | I6: Total Harga Beli | J6: Total Harga Jual | K6: Berat Setoran | L6: Total Harga Beli | M6: Total Harga Jual | N6: Berat Setoran | O6: Total Harga Beli | P6: Total Harga Jual | Q6: Berat Setoran | R6: Total Harga Beli | S6: Total Harga Jual | T6: Berat Setoran | U6: Total Harga Beli | V6: Total Harga Jual | W6: Berat Setoran | X6: Total Harga Beli | Y6: Total Harga Jual | Z6: Berat Setoran | AA6: Total Harga Beli | AB6: Total Harga Jual | AC6: Berat Setoran | AD6: Total Harga Beli | AE6: Total Harga Jual | AF6: Berat Setoran | AG6: Total Harga Beli | AH6: Total Harga Jual | AI6: Berat Setoran | AJ6: Total Harga Beli | AK6: Total Harga Jual | AL6: Berat Setoran | AM6: Total Harga Beli | AN6: Total Harga Jual | AO6: Berat Setoran | AP6: Total Harga Beli | AQ6: Total Harga Jual | AR6: Berat Setoran | AS6: Total Harga Beli | AT6: Total Harga Jual | AU6: Berat Setoran | AV6: Total Harga Beli | AW6: Total Harga Jual
A7: PLASTIK
